Workbook

Sheet aluno 01
B1: PLANILHA DE TREINAMENTO
B2: NOME | C2: Aluno Exemplo
B3: OBJETIVO | C3: Exemplo fictício para teste do template
B5: SEGUNDA | C5: TERÇA | D5: QUARTA | E5: QUINTA | F5: SEXTA
B6: T01 | D6: T02 | F6: T03
A8: OBS
A9: Exemplo fictício: dados criados só para testar o layout.
A11: AQC
B12: SETS | C12: REPS / TEMPO | D12: KG | E12: OBS
A13: Mobilidade de quadril | B13: 2 | C13: 10 | E13: https://www.youtube.com/watch?v=exemplo
A14: Prancha | B14: 3 | C14: 30s
A15: Agachamento goblet | B15: 2 | C15: 10 | D15: 12
A16: ='bloco 01'!C3
A17: SEMANA 01
A18: TREINO 01
B19: SETS | C19: REPS | D19: KG | E19: %1RM / PSE | F19: OBS
A20: ='bloco 01'!$B$6 | B20: ='bloco 01'!C6 | C20: ='bloco 01'!D6 | D20: ='bloco 01'!E6 | E20: =IFERROR(('bloco 01'!F6),"") | F20: ='bloco 01'!G6
A21: ='bloco 01'!$B$7 | B21: ='bloco 01'!C7 | C21: ='bloco 01'!D7 | D21: ='bloco 01'!E7 | E21: =IFERROR(('bloco 01'!F7),"") | F21: ='bloco 01'!G7
A22: ='bloco 01'!$B$8 | B22: ='bloco 01'!C8 | C22: ='bloco 01'!D8 | D22: ='bloco 01'!E8 | E22: =IFERROR(('bloco 01'!F8),"") | F22: ='bloco 01'!G8
A23: ='bloco 01'!$B$9 | B23: ='bloco 01'!C9 | C23: ='bloco 01'!D9 | D23: ='bloco 01'!E9 | E23: =IFERROR(('bloco 01'!F9),"") | F23: ='bloco 01'!G9
A24: ='bloco 01'!$B$10 | B24: ='bloco 01'!C10 | C24: ='bloco 01'!D10 | D24: ='bloco 01'!E10 | E24: =IFERROR(('bloco 01'!F10),"") | F24: ='bloco 01'!G10
A25: ='bloco 01'!$B$11 | B25: ='bloco 01'!C11 | C25: ='bloco 01'!D11 | D25: ='bloco 01'!E11 | E25: =IFERROR(('bloco 01'!F11),"") | F25: ='bloco 01'!G11
A26: ='bloco 01'!$B$12 | B26: ='bloco 01'!C12 | C26: ='bloco 01'!D12 | D26: ='bloco 01'!E12 | E26: =IFERROR(('bloco 01'!F12),"") | F26: ='bloco 01'!G12
A27: ='bloco 01'!$B$13 | B27: ='bloco 01'!C13 | C27: ='bloco 01'!D13 | D27: ='bloco 01'!E13 | E27: =IFERROR(('bloco 01'!F13),"") | F27: ='bloco 01'!G13
A28: ='bloco 01'!$B$14 | B28: ='bloco 01'!C14 | C28: ='bloco 01'!D14 | D28: ='bloco 01'!E14 | E28: =IFERROR(('bloco 01'!F14),"") | F28: ='bloco 01'!G14
A29: ='bloco 01'!$B$15 | B29: ='bloco 01'!C15 | C29: ='bloco 01'!D15 | D29: ='bloco 01'!E15 | E29: =IFERROR(('bloco 01'!F15),"") | F29: ='bloco 01'!G15
A30: TREINO 02
B31: SETS | C31: REPS | D31: KG | E31: %1RM / PSE | F31: OBS
A32: ='bloco 01'!$B$21 | B32: ='bloco 01'!C21 | C32: ='bloco 01'!D21 | D32: ='bloco 01'!E21 | E32: =IFERROR(('bloco 01'!F21),"") | F32: ='bloco 01'!G21
A33: ='bloco 01'!$B$22 | B33: ='bloco 01'!C22 | C33: ='bloco 01'!D22 | D33: ='bloco 01'!E22 | E33: =IFERROR(('bloco 01'!F22),"") | F33: ='bloco 01'!G22
A34: ='bloco 01'!$B$23 | B34: ='bloco 01'!C23 | C34: ='bloco 01'!D23 | D34: ='bloco 01'!E23 | E34: =IFERROR(('bloco 01'!F23),"") | F34: ='bloco 01'!G23
A35: ='bloco 01'!$B$24 | B35: ='bloco 01'!C24 | C35: ='bloco 01'!D24 | D35: ='bloco 01'!E24 | E35: =IFERROR(('bloco 01'!F24),"") | F35: ='bloco 01'!G24
A36: ='bloco 01'!$B$25 | B36: ='bloco 01'!C25 | C36: ='bloco 01'!D25 | D36: ='bloco 01'!E25 | E36: =IFERROR(('bloco 01'!F25),"") | F36: ='bloco 01'!G25
A37: ='bloco 01'!$B$26 | B37: ='bloco 01'!C26 | C37: ='bloco 01'!D26 | D37: ='bloco 01'!E26 | E37: =IFERROR(('bloco 01'!F26),"") | F37: ='bloco 01'!G26
A38: ='bloco 01'!$B$27 | B38: ='bloco 01'!C27 | C38: ='bloco 01'!D27 | D38: ='bloco 01'!E27 | E38: =IFERROR(('bloco 01'!F27),"") | F38: ='bloco 01'!G27
A39: ='bloco 01'!$B$28 | B39: ='bloco 01'!C28 | C39: ='bloco 01'!D28 | D39: ='bloco 01'!E28 | E39: =IFERROR(('bloco 01'!F28),"") | F39: ='bloco 01'!G28
A40: ='bloco 01'!$B$29 | B40: ='bloco 01'!C29 | C40: ='bloco 01'!D29 | D40: ='bloco 01'!E29 | E40: =IFERROR(('bloco 01'!F29),"") | F40: ='bloco 01'!G29
A41: ='bloco 01'!$B$30 | B41: ='bloco 01'!C30 | C41: ='bloco 01'!D30 | D41: ='bloco 01'!E30 | E41: =IFERROR(('bloco 01'!F30),"") | F41: ='bloco 01'!G30
A42: TREINO 03
B43: SETS | C43: REPS | D43: KG | E43: %1RM / PSE | F43: OBS
...

Sheet bloco 01
A1: BLOCO 01
A3: TREINO 01 | C3: 46027 | I3: 46034 | O3: 46041 | U3: 46048
C4: SETS | D4: REPS | E4: KG | F4: %1RM | G4: OBS | I4: SETS | J4: REPS | K4: KG | L4: %1RM | M4: OBS | O4: SETS | P4: REPS | Q4: KG | R4: %1RM | S4: OBS | U4: SETS | V4: REPS | W4: KG | X4: %1RM | Y4: OBS
B5: exercícios | F5: pse | L5: pse | R5: pse | X5: pse
B6: Agachamento | C6: 3 | D6: 5 | E6: 60 | F6: 0.5333 | G6: aquecimento | L6: =IFERROR(__xludf.DUMMYFUNCTION("IFERROR( $K6/ VLOOKUP( IF( REGEXMATCH($B6,""(?i)agachamento""),""Agachamento"", IF( REGEXMATCH($B6,""(?i)supino""),""Supino"", IF( REGEXMATCH($B6,""(?i)terra""),""Terra"", IF( REGEXMATCH($B6,""(?i)desenvolvimento""),""Desenvolvimento"", "&" IF( REGEXMATCH($B6,""(?i)remada""),""Remada"", IF(REGEXMATCH($B6,""(?i)arranco""),""Arranco"",IF(REGEXMATCH($B6,""(?i)arremesso""),""Arremesso"","""")) ) ) ) ) ), prs!$A$6:$D$12, 4, FALSE ) ,"""")"),"") | R6: =IFERROR(__xludf.DUMMYFUNCTION("IFERROR( $Q6/ VLOOKUP( IF( REGEXMATCH($B6,""(?i)agachamento""),""Agachamento"", IF( REGEXMATCH($B6,""(?i)supino""),""Supino"", IF( REGEXMATCH($B6,""(?i)terra""),""Terra"", IF( REGEXMATCH($B6,""(?i)desenvolvimento""),""Desenvolvimento"", "&" IF( REGEXMATCH($B6,""(?i)remada""),""Remada"", IF(REGEXMATCH($B6,""(?i)arranco""),""Arranco"",IF(REGEXMATCH($B6,""(?i)arremesso""),""Arremesso"","""")) ) ) ) ) ), prs!$A$6:$D$12, 4, FALSE ) ,"""")"),"") | X6: =IFERROR(__xludf.DUMMYFUNCTION("IFERROR( $W6/ VLOOKUP( IF( REGEXMATCH($B6,""(?i)agachamento""),""Agachamento"", IF( REGEXMATCH($B6,""(?i)supino""),""Supino"", IF( REGEXMATCH($B6,""(?i)terra""),""Terra"", IF( REGEXMATCH($B6,""(?i)desenvolvimento""),""Desenvolvimento"", "&" IF( REGEXMATCH($B6,""(?i)remada""),""Remada"", IF(REGEXMATCH($B6,""(?i)arranco""),""Arranco"",IF(REGEXMATCH($B6,""(?i)arremesso""),""Arremesso"","""")) ) ) ) ) ), prs!$A$6:$D$12, 4, FALSE ) ,"""")"),"")
B7: Agachamento | C7: 4 | D7: 5 | E7: 85 | F7: 0.7555 | G7: principal | L7: =IFERROR(__xludf.DUMMYFUNCTION("IFERROR( $K7/ VLOOKUP( IF( REGEXMATCH($B7,""(?i)agachamento""),""Agachamento"", IF( REGEXMATCH($B7,""(?i)supino""),""Supino"", IF( REGEXMATCH($B7,""(?i)terra""),""Terra"", IF( REGEXMATCH($B7,""(?i)desenvolvimento""),""Desenvolvimento"", "&" IF( REGEXMATCH($B7,""(?i)remada""),""Remada"", IF(REGEXMATCH($B7,""(?i)arranco""),""Arranco"",IF(REGEXMATCH($B7,""(?i)arremesso""),""Arremesso"","""")) ) ) ) ) ), prs!$A$6:$D$12, 4, FALSE ) ,"""")"),"") | R7: =IFERROR(__xludf.DUMMYFUNCTION("IFERROR( $Q7/ VLOOKUP( IF( REGEXMATCH($B7,""(?i)agachamento""),""Agachamento"", IF( REGEXMATCH($B7,""(?i)supino""),""Supino"", IF( REGEXMATCH($B7,""(?i)terra""),""Terra"", IF( REGEXMATCH($B7,""(?i)desenvolvimento""),""Desenvolvimento"", "&" IF( REGEXMATCH($B7,""(?i)remada""),""Remada"", IF(REGEXMATCH($B7,""(?i)arranco""),""Arranco"",IF(REGEXMATCH($B7,""(?i)arremesso""),""Arremesso"","""")) ) ) ) ) ), prs!$A$6:$D$12, 4, FALSE ) ,"""")"),"") | X7: =IFERROR(__xludf.DUMMYFUNCTION("IFERROR( $W7/ VLOOKUP( IF( REGEXMATCH($B7,""(?i)agachamento""),""Agachamento"", IF( REGEXMATCH($B7,""(?i)supino""),""Supino"", IF( REGEXMATCH($B7,""(?i)terra""),""Terra"", IF( REGEXMATCH($B7,""(?i)desenvolvimento""),""Desenvolvimento"", "&" IF( REGEXMATCH($B7,""(?i)remada""),""Remada"", IF(REGEXMATCH($B7,""(?i)arranco""),""Arranco"",IF(REGEXMATCH($B7,""(?i)arremesso""),""Arremesso"","""")) ) ) ) ) ), prs!$A$6:$D$12, 4, FALSE ) ,"""")"),"")
B8: Supino | C8: 4 | D8: 6 | E8: 60 | F8: 0.7618 | L8: =IFERROR(__xludf.DUMMYFUNCTION("IFERROR( $K8/ VLOOKUP( IF( REGEXMATCH($B8,""(?i)agachamento""),""Agachamento"", IF( REGEXMATCH($B8,""(?i)supino""),""Supino"", IF( REGEXMATCH($B8,""(?i)terra""),""Terra"", IF( REGEXMATCH($B8,""(?i)desenvolvimento""),""Desenvolvimento"", "&" IF( REGEXMATCH($B8,""(?i)remada""),""Remada"", IF(REGEXMATCH($B8,""(?i)arranco""),""Arranco"",IF(REGEXMATCH($B8,""(?i)arremesso""),""Arremesso"","""")) ) ) ) ) ), prs!$A$6:$D$12, 4, FALSE ) ,"""")"),"") | R8: =IFERROR(__xludf.DUMMYFUNCTION("IFERROR( $Q8/ VLOOKUP( IF( REGEXMATCH($B8,""(?i)agachamento""),""Agachamento"", IF( REGEXMATCH($B8,""(?i)supino""),""Supino"", IF( REGEXMATCH($B8,""(?i)terra""),""Terra"", IF( REGEXMATCH($B8,""(?i)desenvolvimento""),""Desenvolvimento"", "&" IF( REGEXMATCH($B8,""(?i)remada""),""Remada"", IF(REGEXMATCH($B8,""(?i)arranco""),""Arranco"",IF(REGEXMATCH($B8,""(?i)arremesso""),""Arremesso"","""")) ) ) ) ) ), prs!$A$6:$D$12, 4, FALSE ) ,"""")"),"") | X8: =IFERROR(__xludf.DUMMYFUNCTION("IFERROR( $W8/ VLOOKUP( IF( REGEXMATCH($B8,""(?i)agachamento""),""Agachamento"", IF( REGEXMATCH($B8,""(?i)supino""),""Supino"", IF( REGEXMATCH($B8,""(?i)terra""),""Terra"", IF( REGEXMATCH($B8,""(?i)desenvolvimento""),""Desenvolvimento"", "&" IF( REGEXMATCH($B8,""(?i)remada""),""Remada"", IF(REGEXMATCH($B8,""(?i)arranco""),""Arranco"",IF(REGEXMATCH($B8,""(?i)arremesso""),""Arremesso"","""")) ) ) ) ) ), prs!$A$6:$D$12, 4, FALSE ) ,"""")"),"")
B9: Remada curvada | C9: 3 | D9: 10 | E9: 40 | G9: biset | L9: =IFERROR(__xludf.DUMMYFUNCTION("IFERROR( $K9/ VLOOKUP( IF( REGEXMATCH($B9,""(?i)agachamento""),""Agachamento"", IF( REGEXMATCH($B9,""(?i)supino""),""Supino"", IF( REGEXMATCH($B9,""(?i)terra""),""Terra"", IF( REGEXMATCH($B9,""(?i)desenvolvimento""),""Desenvolvimento"", "&" IF( REGEXMATCH($B9,""(?i)remada""),""Remada"", IF(REGEXMATCH($B9,""(?i)arranco""),""Arranco"",IF(REGEXMATCH($B9,""(?i)arremesso""),""Arremesso"","""")) ) ) ) ) ), prs!$A$6:$D$12, 4, FALSE ) ,"""")"),"") | R9: =IFERROR(__xludf.DUMMYFUNCTION("IFERROR( $Q9/ VLOOKUP( IF( REGEXMATCH($B9,""(?i)agachamento""),""Agachamento"", IF( REGEXMATCH($B9,""(?i)supino""),""Supino"", IF( REGEXMATCH($B9,""(?i)terra""),""Terra"", IF( REGEXMATCH($B9,""(?i)desenvolvimento""),""Desenvolvimento"", "&" IF( REGEXMATCH($B9,""(?i)remada""),""Remada"", IF(REGEXMATCH($B9,""(?i)arranco""),""Arranco"",IF(REGEXMATCH($B9,""(?i)arremesso""),""Arremesso"","""")) ) ) ) ) ), prs!$A$6:$D$12, 4, FALSE ) ,"""")"),"") | X9: =IFERROR(__xludf.DUMMYFUNCTION("IFERROR( $W9/ VLOOKUP( IF( REGEXMATCH($B9,""(?i)agachamento""),""Agachamento"", IF( REGEXMATCH($B9,""(?i)supino""),""Supino"", IF( REGEXMATCH($B9,""(?i)terra""),""Terra"", IF( REGEXMATCH($B9,""(?i)desenvolvimento""),""Desenvolvimento"", "&" IF( REGEXMATCH($B9,""(?i)remada""),""Remada"", IF(REGEXMATCH($B9,""(?i)arranco""),""Arranco"",IF(REGEXMATCH($B9,""(?i)arremesso""),""Arremesso"","""")) ) ) ) ) ), prs!$A$6:$D$12, 4, FALSE ) ,"""")"),"")
B10: Prancha lateral | C10: 3 | D10: 30s | G10: biset | L10: =IFERROR(__xludf.DUMMYFUNCTION("IFERROR( $K10/ VLOOKUP( IF( REGEXMATCH($B10,""(?i)agachamento""),""Agachamento"", IF( REGEXMATCH($B10,""(?i)supino""),""Supino"", IF( REGEXMATCH($B10,""(?i)terra""),""Terra"", IF( REGEXMATCH($B10,""(?i)desenvolvimento""),""Desenvolvimento"&""", IF( REGEXMATCH($B10,""(?i)remada""),""Remada"", IF(REGEXMATCH($B10,""(?i)arranco""),""Arranco"",IF(REGEXMATCH($B10,""(?i)arremesso""),""Arremesso"","""")) ) ) ) ) ), prs!$A$6:$D$12, 4, FALSE ) ,"""")"),"") | R10: =IFERROR(__xludf.DUMMYFUNCTION("IFERROR( $Q10/ VLOOKUP( IF( REGEXMATCH($B10,""(?i)agachamento""),""Agachamento"", IF( REGEXMATCH($B10,""(?i)supino""),""Supino"", IF( REGEXMATCH($B10,""(?i)terra""),""Terra"", IF( REGEXMATCH($B10,""(?i)desenvolvimento""),""Desenvolvimento"&""", IF( REGEXMATCH($B10,""(?i)remada""),""Remada"", IF(REGEXMATCH($B10,""(?i)arranco""),""Arranco"",IF(REGEXMATCH($B10,""(?i)arremesso""),""Arremesso"","""")) ) ) ) ) ), prs!$A$6:$D$12, 4, FALSE ) ,"""")"),"") | X10: =IFERROR(__xludf.DUMMYFUNCTION("IFERROR( $W10/ VLOOKUP( IF( REGEXMATCH($B10,""(?i)agachamento""),""Agachamento"", IF( REGEXMATCH($B10,""(?i)supino""),""Supino"", IF( REGEXMATCH($B10,""(?i)terra""),""Terra"", IF( REGEXMATCH($B10,""(?i)desenvolvimento""),""Desenvolvimento"&""", IF( REGEXMATCH($B10,""(?i)remada""),""Remada"", IF(REGEXMATCH($B10,""(?i)arranco""),""Arranco"",IF(REGEXMATCH($B10,""(?i)arremesso""),""Arremesso"","""")) ) ) ) ) ), prs!$A$6:$D$12, 4, FALSE ) ,"""")"),"")
F11: =IFERROR(__xludf.DUMMYFUNCTION("IFERROR( $E11/ VLOOKUP( IF( REGEXMATCH($B11,""(?i)agachamento""),""Agachamento"", IF( REGEXMATCH($B11,""(?i)supino""),""Supino"", IF( REGEXMATCH($B11,""(?i)terra""),""Terra"", IF( REGEXMATCH($B11,""(?i)desenvolvimento""),""Desenvolvimento"&""", IF( REGEXMATCH($B11,""(?i)remada""),""Remada"", IF(REGEXMATCH($B11,""(?i)arranco""),""Arranco"",IF(REGEXMATCH($B11,""(?i)arremesso""),""Arremesso"","""")) ) ) ) ) ), prs!$A$6:$D$12, 4, FALSE ) ,"""")"),"") | L11: =IFERROR(__xludf.DUMMYFUNCTION("IFERROR( $K11/ VLOOKUP( IF( REGEXMATCH($B11,""(?i)agachamento""),""Agachamento"", IF( REGEXMATCH($B11,""(?i)supino""),""Supino"", IF( REGEXMATCH($B11,""(?i)terra""),""Terra"", IF( REGEXMATCH($B11,""(?i)desenvolvimento""),""Desenvolvimento"&""", IF( REGEXMATCH($B11,""(?i)remada""),""Remada"", IF(REGEXMATCH($B11,""(?i)arranco""),""Arranco"",IF(REGEXMATCH($B11,""(?i)arremesso""),""Arremesso"","""")) ) ) ) ) ), prs!$A$6:$D$12, 4, FALSE ) ,"""")"),"") | R11: =IFERROR(__xludf.DUMMYFUNCTION("IFERROR( $Q11/ VLOOKUP( IF( REGEXMATCH($B11,""(?i)agachamento""),""Agachamento"", IF( REGEXMATCH($B11,""(?i)supino""),""Supino"", IF( REGEXMATCH($B11,""(?i)terra""),""Terra"", IF( REGEXMATCH($B11,""(?i)desenvolvimento""),""Desenvolvimento"&""", IF( REGEXMATCH($B11,""(?i)remada""),""Remada"", IF(REGEXMATCH($B11,""(?i)arranco""),""Arranco"",IF(REGEXMATCH($B11,""(?i)arremesso""),""Arremesso"","""")) ) ) ) ) ), prs!$A$6:$D$12, 4, FALSE ) ,"""")"),"") | X11: =IFERROR(__xludf.DUMMYFUNCTION("IFERROR( $W11/ VLOOKUP( IF( REGEXMATCH($B11,""(?i)agachamento""),""Agachamento"", IF( REGEXMATCH($B11,""(?i)supino""),""Supino"", IF( REGEXMATCH($B11,""(?i)terra""),""Terra"", IF( REGEXMATCH($B11,""(?i)desenvolvimento""),""Desenvolvimento"&""", IF( REGEXMATCH($B11,""(?i)remada""),""Remada"", IF(REGEXMATCH($B11,""(?i)arranco""),""Arranco"",IF(REGEXMATCH($B11,""(?i)arremesso""),""Arremesso"","""")) ) ) ) ) ), prs!$A$6:$D$12, 4, FALSE ) ,"""")"),"")
F12: =IFERROR(__xludf.DUMMYFUNCTION("IFERROR( $E12/ VLOOKUP( IF( REGEXMATCH($B12,""(?i)agachamento""),""Agachamento"", IF( REGEXMATCH($B12,""(?i)supino""),""Supino"", IF( REGEXMATCH($B12,""(?i)terra""),""Terra"", IF( REGEXMATCH($B12,""(?i)desenvolvimento""),""Desenvolvimento"&""", IF( REGEXMATCH($B12,""(?i)remada""),""Remada"", IF(REGEXMATCH($B12,""(?i)arranco""),""Arranco"",IF(REGEXMATCH($B12,""(?i)arremesso""),""Arremesso"","""")) ) ) ) ) ), prs!$A$6:$D$12, 4, FALSE ) ,"""")"),"") | L12: =IFERROR(__xludf.DUMMYFUNCTION("IFERROR( $K12/ VLOOKUP( IF( REGEXMATCH($B12,""(?i)agachamento""),""Agachamento"", IF( REGEXMATCH($B12,""(?i)supino""),""Supino"", IF( REGEXMATCH($B12,""(?i)terra""),""Terra"", IF( REGEXMATCH($B12,""(?i)desenvolvimento""),""Desenvolvimento"&""", IF( REGEXMATCH($B12,""(?i)remada""),""Remada"", IF(REGEXMATCH($B12,""(?i)arranco""),""Arranco"",IF(REGEXMATCH($B12,""(?i)arremesso""),""Arremesso"","""")) ) ) ) ) ), prs!$A$6:$D$12, 4, FALSE ) ,"""")"),"") | R12: =IFERROR(__xludf.DUMMYFUNCTION("IFERROR( $Q12/ VLOOKUP( IF( REGEXMATCH($B12,""(?i)agachamento""),""Agachamento"", IF( REGEXMATCH($B12,""(?i)supino""),""Supino"", IF( REGEXMATCH($B12,""(?i)terra""),""Terra"", IF( REGEXMATCH($B12,""(?i)desenvolvimento""),""Desenvolvimento"&""", IF( REGEXMATCH($B12,""(?i)remada""),""Remada"", IF(REGEXMATCH($B12,""(?i)arranco""),""Arranco"",IF(REGEXMATCH($B12,""(?i)arremesso""),""Arremesso"","""")) ) ) ) ) ), prs!$A$6:$D$12, 4, FALSE ) ,"""")"),"") | X12: =IFERROR(__xludf.DUMMYFUNCTION("IFERROR( $W12/ VLOOKUP( IF( REGEXMATCH($B12,""(?i)agachamento""),""Agachamento"", IF( REGEXMATCH($B12,""(?i)supino""),""Supino"", IF( REGEXMATCH($B12,""(?i)terra""),""Terra"", IF( REGEXMATCH($B12,""(?i)desenvolvimento""),""Desenvolvimento"&""", IF( REGEXMATCH($B12,""(?i)remada""),""Remada"", IF(REGEXMATCH($B12,""(?i)arranco""),""Arranco"",IF(REGEXMATCH($B12,""(?i)arremesso""),""Arremesso"","""")) ) ) ) ) ), prs!$A$6:$D$12, 4, FALSE ) ,"""")"),"")
F13: =IFERROR(__xludf.DUMMYFUNCTION("IFERROR( $E13/ VLOOKUP( IF( REGEXMATCH($B13,""(?i)agachamento""),""Agachamento"", IF( REGEXMATCH($B13,""(?i)supino""),""Supino"", IF( REGEXMATCH($B13,""(?i)terra""),""Terra"", IF( REGEXMATCH($B13,""(?i)desenvolvimento""),""Desenvolvimento"&""", IF( REGEXMATCH($B13,""(?i)remada""),""Remada"", IF(REGEXMATCH($B13,""(?i)arranco""),""Arranco"",IF(REGEXMATCH($B13,""(?i)arremesso""),""Arremesso"","""")) ) ) ) ) ), prs!$A$6:$D$12, 4, FALSE ) ,"""")"),"") | L13: =IFERROR(__xludf.DUMMYFUNCTION("IFERROR( $K13/ VLOOKUP( IF( REGEXMATCH($B13,""(?i)agachamento""),""Agachamento"", IF( REGEXMATCH($B13,""(?i)supino""),""Supino"", IF( REGEXMATCH($B13,""(?i)terra""),""Terra"", IF( REGEXMATCH($B13,""(?i)desenvolvimento""),""Desenvolvimento"&""", IF( REGEXMATCH($B13,""(?i)remada""),""Remada"", IF(REGEXMATCH($B13,""(?i)arranco""),""Arranco"",IF(REGEXMATCH($B13,""(?i)arremesso""),""Arremesso"","""")) ) ) ) ) ), prs!$A$6:$D$12, 4, FALSE ) ,"""")"),"") | R13: =IFERROR(__xludf.DUMMYFUNCTION("IFERROR( $Q13/ VLOOKUP( IF( REGEXMATCH($B13,""(?i)agachamento""),""Agachamento"", IF( REGEXMATCH($B13,""(?i)supino""),""Supino"", IF( REGEXMATCH($B13,""(?i)terra""),""Terra"", IF( REGEXMATCH($B13,""(?i)desenvolvimento""),""Desenvolvimento"&""", IF( REGEXMATCH($B13,""(?i)remada""),""Remada"", IF(REGEXMATCH($B13,""(?i)arranco""),""Arranco"",IF(REGEXMATCH($B13,""(?i)arremesso""),""Arremesso"","""")) ) ) ) ) ), prs!$A$6:$D$12, 4, FALSE ) ,"""")"),"") | X13: =IFERROR(__xludf.DUMMYFUNCTION("IFERROR( $W13/ VLOOKUP( IF( REGEXMATCH($B13,""(?i)agachamento""),""Agachamento"", IF( REGEXMATCH($B13,""(?i)supino""),""Supino"", IF( REGEXMATCH($B13,""(?i)terra""),""Terra"", IF( REGEXMATCH($B13,""(?i)desenvolvimento""),""Desenvolvimento"&""", IF( REGEXMATCH($B13,""(?i)remada""),""Remada"", IF(REGEXMATCH($B13,""(?i)arranco""),""Arranco"",IF(REGEXMATCH($B13,""(?i)arremesso""),""Arremesso"","""")) ) ) ) ) ), prs!$A$6:$D$12, 4, FALSE ) ,"""")"),"")
F14: =IFERROR(__xludf.DUMMYFUNCTION("IFERROR( $E14/ VLOOKUP( IF( REGEXMATCH($B14,""(?i)agachamento""),""Agachamento"", IF( REGEXMATCH($B14,""(?i)supino""),""Supino"", IF( REGEXMATCH($B14,""(?i)terra""),""Terra"", IF( REGEXMATCH($B14,""(?i)desenvolvimento""),""Desenvolvimento"&""", IF( REGEXMATCH($B14,""(?i)remada""),""Remada"", IF(REGEXMATCH($B14,""(?i)arranco""),""Arranco"",IF(REGEXMATCH($B14,""(?i)arremesso""),""Arremesso"","""")) ) ) ) ) ), prs!$A$6:$D$12, 4, FALSE ) ,"""")"),"") | L14: =IFERROR(__xludf.DUMMYFUNCTION("IFERROR( $K14/ VLOOKUP( IF( REGEXMATCH($B14,""(?i)agachamento""),""Agachamento"", IF( REGEXMATCH($B14,""(?i)supino""),""Supino"", IF( REGEXMATCH($B14,""(?i)terra""),""Terra"", IF( REGEXMATCH($B14,""(?i)desenvolvimento""),""Desenvolvimento"&""", IF( REGEXMATCH($B14,""(?i)remada""),""Remada"", IF(REGEXMATCH($B14,""(?i)arranco""),""Arranco"",IF(REGEXMATCH($B14,""(?i)arremesso""),""Arremesso"","""")) ) ) ) ) ), prs!$A$6:$D$12, 4, FALSE ) ,"""")"),"") | R14: =IFERROR(__xludf.DUMMYFUNCTION("IFERROR( $Q14/ VLOOKUP( IF( REGEXMATCH($B14,""(?i)agachamento""),""Agachamento"", IF( REGEXMATCH($B14,""(?i)supino""),""Supino"", IF( REGEXMATCH($B14,""(?i)terra""),""Terra"", IF( REGEXMATCH($B14,""(?i)desenvolvimento""),""Desenvolvimento"&""", IF( REGEXMATCH($B14,""(?i)remada""),""Remada"", IF(REGEXMATCH($B14,""(?i)arranco""),""Arranco"",IF(REGEXMATCH($B14,""(?i)arremesso""),""Arremesso"","""")) ) ) ) ) ), prs!$A$6:$D$12, 4, FALSE ) ,"""")"),"") | X14: =IFERROR(__xludf.DUMMYFUNCTION("IFERROR( $W14/ VLOOKUP( IF( REGEXMATCH($B14,""(?i)agachamento""),""Agachamento"", IF( REGEXMATCH($B14,""(?i)supino""),""Supino"", IF( REGEXMATCH($B14,""(?i)terra""),""Terra"", IF( REGEXMATCH($B14,""(?i)desenvolvimento""),""Desenvolvimento"&""", IF( REGEXMATCH($B14,""(?i)remada""),""Remada"", IF(REGEXMATCH($B14,""(?i)arranco""),""Arranco"",IF(REGEXMATCH($B14,""(?i)arremesso""),""Arremesso"","""")) ) ) ) ) ), prs!$A$6:$D$12, 4, FALSE ) ,"""")"),"")
F15: =IFERROR(__xludf.DUMMYFUNCTION("IFERROR( $E15/ VLOOKUP( IF( REGEXMATCH($B15,""(?i)agachamento""),""Agachamento"", IF( REGEXMATCH($B15,""(?i)supino""),""Supino"", IF( REGEXMATCH($B15,""(?i)terra""),""Terra"", IF( REGEXMATCH($B15,""(?i)desenvolvimento""),""Desenvolvimento"&""", IF( REGEXMATCH($B15,""(?i)remada""),""Remada"", IF(REGEXMATCH($B15,""(?i)arranco""),""Arranco"",IF(REGEXMATCH($B15,""(?i)arremesso""),""Arremesso"","""")) ) ) ) ) ), prs!$A$6:$D$12, 4, FALSE ) ,"""")"),"") | L15: =IFERROR(__xludf.DUMMYFUNCTION("IFERROR( $K15/ VLOOKUP( IF( REGEXMATCH($B15,""(?i)agachamento""),""Agachamento"", IF( REGEXMATCH($B15,""(?i)supino""),""Supino"", IF( REGEXMATCH($B15,""(?i)terra""),""Terra"", IF( REGEXMATCH($B15,""(?i)desenvolvimento""),""Desenvolvimento"&""", IF( REGEXMATCH($B15,""(?i)remada""),""Remada"", IF(REGEXMATCH($B15,""(?i)arranco""),""Arranco"",IF(REGEXMATCH($B15,""(?i)arremesso""),""Arremesso"","""")) ) ) ) ) ), prs!$A$6:$D$12, 4, FALSE ) ,"""")"),"") | R15: =IFERROR(__xludf.DUMMYFUNCTION("IFERROR( $Q15/ VLOOKUP( IF( REGEXMATCH($B15,""(?i)agachamento""),""Agachamento"", IF( REGEXMATCH($B15,""(?i)supino""),""Supino"", IF( REGEXMATCH($B15,""(?i)terra""),""Terra"", IF( REGEXMATCH($B15,""(?i)desenvolvimento""),""Desenvolvimento"&""", IF( REGEXMATCH($B15,""(?i)remada""),""Remada"", IF(REGEXMATCH($B15,""(?i)arranco""),""Arranco"",IF(REGEXMATCH($B15,""(?i)arremesso""),""Arremesso"","""")) ) ) ) ) ), prs!$A$6:$D$12, 4, FALSE ) ,"""")"),"") | X15: =IFERROR(__xludf.DUMMYFUNCTION("IFERROR( $W15/ VLOOKUP( IF( REGEXMATCH($B15,""(?i)agachamento""),""Agachamento"", IF( REGEXMATCH($B15,""(?i)supino""),""Supino"", IF( REGEXMATCH($B15,""(?i)terra""),""Terra"", IF( REGEXMATCH($B15,""(?i)desenvolvimento""),""Desenvolvimento"&""", IF( REGEXMATCH($B15,""(?i)remada""),""Remada"", IF(REGEXMATCH($B15,""(?i)arranco""),""Arranco"",IF(REGEXMATCH($B15,""(?i)arremesso""),""Arremesso"","""")) ) ) ) ) ), prs!$A$6:$D$12, 4, FALSE ) ,"""")"),"")
C16: SEMANA 01 | I16: SEMANA 02 | O16: SEMANA 03 | U16: SEMANA 04
A18: TREINO 02
C19: SETS | D19: REPS | E19: KG | F19: %1RM | G19: OBS | I19: SETS | J19: REPS | K19: KG | L19: %1RM | M19: OBS | O19: SETS | P19: REPS | Q19: KG | R19: %1RM | S19: OBS | U19: SETS | V19: REPS | W19: KG | X19: %1RM | Y19: OBS
B20: exercícios | F20: pse | L20: pse | R20: pse | X20: pse
B21: Arranco | C21: 5 | D21: 3 | E21: 35 | F21: 0.6611 | G21: gravar | L21: =IFERROR(__xludf.DUMMYFUNCTION("IFERROR( $K21/ VLOOKUP( IF( REGEXMATCH($B21,""(?i)agachamento""),""Agachamento"", IF( REGEXMATCH($B21,""(?i)supino""),""Supino"", IF( REGEXMATCH($B21,""(?i)terra""),""Terra"", IF( REGEXMATCH($B21,""(?i)desenvolvimento""),""Desenvolvimento"&""", IF( REGEXMATCH($B21,""(?i)remada""),""Remada"", IF(REGEXMATCH($B21,""(?i)arranco""),""Arranco"",IF(REGEXMATCH($B21,""(?i)arremesso""),""Arremesso"","""")) ) ) ) ) ), prs!$A$6:$D$12, 4, FALSE ) ,"""")"),"") | R21: =IFERROR(__xludf.DUMMYFUNCTION("IFERROR( $Q21/ VLOOKUP( IF( REGEXMATCH($B21,""(?i)agachamento""),""Agachamento"", IF( REGEXMATCH($B21,""(?i)supino""),""Supino"", IF( REGEXMATCH($B21,""(?i)terra""),""Terra"", IF( REGEXMATCH($B21,""(?i)desenvolvimento""),""Desenvolvimento"&""", IF( REGEXMATCH($B21,""(?i)remada""),""Remada"", IF(REGEXMATCH($B21,""(?i)arranco""),""Arranco"",IF(REGEXMATCH($B21,""(?i)arremesso""),""Arremesso"","""")) ) ) ) ) ), prs!$A$6:$D$12, 4, FALSE ) ,"""")"),"") | X21: =IFERROR(__xludf.DUMMYFUNCTION("IFERROR( $W21/ VLOOKUP( IF( REGEXMATCH($B21,""(?i)agachamento""),""Agachamento"", IF( REGEXMATCH($B21,""(?i)supino""),""Supino"", IF( REGEXMATCH($B21,""(?i)terra""),""Terra"", IF( REGEXMATCH($B21,""(?i)desenvolvimento""),""Desenvolvimento"&""", IF( REGEXMATCH($B21,""(?i)remada""),""Remada"", IF(REGEXMATCH($B21,""(?i)arranco""),""Arranco"",IF(REGEXMATCH($B21,""(?i)arremesso""),""Arremesso"","""")) ) ) ) ) ), prs!$A$6:$D$12, 4, FALSE ) ,"""")"),"")
B22: Levantamento terra | C22: 4 | D22: 4 | E22: 100 | F22: 0.7265 | L22: =IFERROR(__xludf.DUMMYFUNCTION("IFERROR( $K22/ VLOOKUP( IF( REGEXMATCH($B22,""(?i)agachamento""),""Agachamento"", IF( REGEXMATCH($B22,""(?i)supino""),""Supino"", IF( REGEXMATCH($B22,""(?i)terra""),""Terra"", IF( REGEXMATCH($B22,""(?i)desenvolvimento""),""Desenvolvimento"&""", IF( REGEXMATCH($B22,""(?i)remada""),""Remada"", IF(REGEXMATCH($B22,""(?i)arranco""),""Arranco"",IF(REGEXMATCH($B22,""(?i)arremesso""),""Arremesso"","""")) ) ) ) ) ), prs!$A$6:$D$12, 4, FALSE ) ,"""")"),"") | R22: =IFERROR(__xludf.DUMMYFUNCTION("IFERROR( $Q22/ VLOOKUP( IF( REGEXMATCH($B22,""(?i)agachamento""),""Agachamento"", IF( REGEXMATCH($B22,""(?i)supino""),""Supino"", IF( REGEXMATCH($B22,""(?i)terra""),""Terra"", IF( REGEXMATCH($B22,""(?i)desenvolvimento""),""Desenvolvimento"&""", IF( REGEXMATCH($B22,""(?i)remada""),""Remada"", IF(REGEXMATCH($B22,""(?i)arranco""),""Arranco"",IF(REGEXMATCH($B22,""(?i)arremesso""),""Arremesso"","""")) ) ) ) ) ), prs!$A$6:$D$12, 4, FALSE ) ,"""")"),"") | X22: =IFERROR(__xludf.DUMMYFUNCTION("IFERROR( $W22/ VLOOKUP( IF( REGEXMATCH($B22,""(?i)agachamento""),""Agachamento"", IF( REGEXMATCH($B22,""(?i)supino""),""Supino"", IF( REGEXMATCH($B22,""(?i)terra""),""Terra"", IF( REGEXMATCH($B22,""(?i)desenvolvimento""),""Desenvolvimento"&""", IF( REGEXMATCH($B22,""(?i)remada""),""Remada"", IF(REGEXMATCH($B22,""(?i)arranco""),""Arranco"",IF(REGEXMATCH($B22,""(?i)arremesso""),""Arremesso"","""")) ) ) ) ) ), prs!$A$6:$D$12, 4, FALSE ) ,"""")"),"")
B23: Desenvolvimento com halteres | C23: 3 | D23: 8 - 12 | E23: 14 | L23: =IFERROR(__xludf.DUMMYFUNCTION("IFERROR( $K23/ VLOOKUP( IF( REGEXMATCH($B23,""(?i)agachamento""),""Agachamento"", IF( REGEXMATCH($B23,""(?i)supino""),""Supino"", IF( REGEXMATCH($B23,""(?i)terra""),""Terra"", IF( REGEXMATCH($B23,""(?i)desenvolvimento""),""Desenvolvimento"&""", IF( REGEXMATCH($B23,""(?i)remada""),""Remada"", IF(REGEXMATCH($B23,""(?i)arranco""),""Arranco"",IF(REGEXMATCH($B23,""(?i)arremesso""),""Arremesso"","""")) ) ) ) ) ), prs!$A$6:$D$12, 4, FALSE ) ,"""")"),"") | R23: =IFERROR(__xludf.DUMMYFUNCTION("IFERROR( $Q23/ VLOOKUP( IF( REGEXMATCH($B23,""(?i)agachamento""),""Agachamento"", IF( REGEXMATCH($B23,""(?i)supino""),""Supino"", IF( REGEXMATCH($B23,""(?i)terra""),""Terra"", IF( REGEXMATCH($B23,""(?i)desenvolvimento""),""Desenvolvimento"&""", IF( REGEXMATCH($B23,""(?i)remada""),""Remada"", IF(REGEXMATCH($B23,""(?i)arranco""),""Arranco"",IF(REGEXMATCH($B23,""(?i)arremesso""),""Arremesso"","""")) ) ) ) ) ), prs!$A$6:$D$12, 4, FALSE ) ,"""")"),"") | X23: =IFERROR(__xludf.DUMMYFUNCTION("IFERROR( $W23/ VLOOKUP( IF( REGEXMATCH($B23,""(?i)agachamento""),""Agachamento"", IF( REGEXMATCH($B23,""(?i)supino""),""Supino"", IF( REGEXMATCH($B23,""(?i)terra""),""Terra"", IF( REGEXMATCH($B23,""(?i)desenvolvimento""),""Desenvolvimento"&""", IF( REGEXMATCH($B23,""(?i)remada""),""Remada"", IF(REGEXMATCH($B23,""(?i)arranco""),""Arranco"",IF(REGEXMATCH($B23,""(?i)arremesso""),""Arremesso"","""")) ) ) ) ) ), prs!$A$6:$D$12, 4, FALSE ) ,"""")"),"")
B24: Afundo | C24: 3 | D24: 10 | E24: 20 | L24: =IFERROR(__xludf.DUMMYFUNCTION("IFERROR( $K24/ VLOOKUP( IF( REGEXMATCH($B24,""(?i)agachamento""),""Agachamento"", IF( REGEXMATCH($B24,""(?i)supino""),""Supino"", IF( REGEXMATCH($B24,""(?i)terra""),""Terra"", IF( REGEXMATCH($B24,""(?i)desenvolvimento""),""Desenvolvimento"&""", IF( REGEXMATCH($B24,""(?i)remada""),""Remada"", IF(REGEXMATCH($B24,""(?i)arranco""),""Arranco"",IF(REGEXMATCH($B24,""(?i)arremesso""),""Arremesso"","""")) ) ) ) ) ), prs!$A$6:$D$12, 4, FALSE ) ,"""")"),"") | R24: =IFERROR(__xludf.DUMMYFUNCTION("IFERROR( $Q24/ VLOOKUP( IF( REGEXMATCH($B24,""(?i)agachamento""),""Agachamento"", IF( REGEXMATCH($B24,""(?i)supino""),""Supino"", IF( REGEXMATCH($B24,""(?i)terra""),""Terra"", IF( REGEXMATCH($B24,""(?i)desenvolvimento""),""Desenvolvimento"&""", IF( REGEXMATCH($B24,""(?i)remada""),""Remada"", IF(REGEXMATCH($B24,""(?i)arranco""),""Arranco"",IF(REGEXMATCH($B24,""(?i)arremesso""),""Arremesso"","""")) ) ) ) ) ), prs!$A$6:$D$12, 4, FALSE ) ,"""")"),"") | X24: =IFERROR(__xludf.DUMMYFUNCTION("IFERROR( $W24/ VLOOKUP( IF( REGEXMATCH($B24,""(?i)agachamento""),""Agachamento"", IF( REGEXMATCH($B24,""(?i)supino""),""Supino"", IF( REGEXMATCH($B24,""(?i)terra""),""Terra"", IF( REGEXMATCH($B24,""(?i)desenvolvimento""),""Desenvolvimento"&""", IF( REGEXMATCH($B24,""(?i)remada""),""Remada"", IF(REGEXMATCH($B24,""(?i)arranco""),""Arranco"",IF(REGEXMATCH($B24,""(?i)arremesso""),""Arremesso"","""")) ) ) ) ) ), prs!$A$6:$D$12, 4, FALSE ) ,"""")"),"")
F25: =IFERROR(__xludf.DUMMYFUNCTION("IFERROR( $E25/ VLOOKUP( IF( REGEXMATCH($B25,""(?i)agachamento""),""Agachamento"", IF( REGEXMATCH($B25,""(?i)supino""),""Supino"", IF( REGEXMATCH($B25,""(?i)terra""),""Terra"", IF( REGEXMATCH($B25,""(?i)desenvolvimento""),""Desenvolvimento"&""", IF( REGEXMATCH($B25,""(?i)remada""),""Remada"", IF(REGEXMATCH($B25,""(?i)arranco""),""Arranco"",IF(REGEXMATCH($B25,""(?i)arremesso""),""Arremesso"","""")) ) ) ) ) ), prs!$A$6:$D$12, 4, FALSE ) ,"""")"),"") | L25: =IFERROR(__xludf.DUMMYFUNCTION("IFERROR( $K25/ VLOOKUP( IF( REGEXMATCH($B25,""(?i)agachamento""),""Agachamento"", IF( REGEXMATCH($B25,""(?i)supino""),""Supino"", IF( REGEXMATCH($B25,""(?i)terra""),""Terra"", IF( REGEXMATCH($B25,""(?i)desenvolvimento""),""Desenvolvimento"&""", IF( REGEXMATCH($B25,""(?i)remada""),""Remada"", IF(REGEXMATCH($B25,""(?i)arranco""),""Arranco"",IF(REGEXMATCH($B25,""(?i)arremesso""),""Arremesso"","""")) ) ) ) ) ), prs!$A$6:$D$12, 4, FALSE ) ,"""")"),"") | R25: =IFERROR(__xludf.DUMMYFUNCTION("IFERROR( $Q25/ VLOOKUP( IF( REGEXMATCH($B25,""(?i)agachamento""),""Agachamento"", IF( REGEXMATCH($B25,""(?i)supino""),""Supino"", IF( REGEXMATCH($B25,""(?i)terra""),""Terra"", IF( REGEXMATCH($B25,""(?i)desenvolvimento""),""Desenvolvimento"&""", IF( REGEXMATCH($B25,""(?i)remada""),""Remada"", IF(REGEXMATCH($B25,""(?i)arranco""),""Arranco"",IF(REGEXMATCH($B25,""(?i)arremesso""),""Arremesso"","""")) ) ) ) ) ), prs!$A$6:$D$12, 4, FALSE ) ,"""")"),"") | X25: =IFERROR(__xludf.DUMMYFUNCTION("IFERROR( $W25/ VLOOKUP( IF( REGEXMATCH($B25,""(?i)agachamento""),""Agachamento"", IF( REGEXMATCH($B25,""(?i)supino""),""Supino"", IF( REGEXMATCH($B25,""(?i)terra""),""Terra"", IF( REGEXMATCH($B25,""(?i)desenvolvimento""),""Desenvolvimento"&""", IF( REGEXMATCH($B25,""(?i)remada""),""Remada"", IF(REGEXMATCH($B25,""(?i)arranco""),""Arranco"",IF(REGEXMATCH($B25,""(?i)arremesso""),""Arremesso"","""")) ) ) ) ) ), prs!$A$6:$D$12, 4, FALSE ) ,"""")"),"")
F26: =IFERROR(__xludf.DUMMYFUNCTION("IFERROR( $E26/ VLOOKUP( IF( REGEXMATCH($B26,""(?i)agachamento""),""Agachamento"", IF( REGEXMATCH($B26,""(?i)supino""),""Supino"", IF( REGEXMATCH($B26,""(?i)terra""),""Terra"", IF( REGEXMATCH($B26,""(?i)desenvolvimento""),""Desenvolvimento"&""", IF( REGEXMATCH($B26,""(?i)remada""),""Remada"", IF(REGEXMATCH($B26,""(?i)arranco""),""Arranco"",IF(REGEXMATCH($B26,""(?i)arremesso""),""Arremesso"","""")) ) ) ) ) ), prs!$A$6:$D$12, 4, FALSE ) ,"""")"),"") | L26: =IFERROR(__xludf.DUMMYFUNCTION("IFERROR( $K26/ VLOOKUP( IF( REGEXMATCH($B26,""(?i)agachamento""),""Agachamento"", IF( REGEXMATCH($B26,""(?i)supino""),""Supino"", IF( REGEXMATCH($B26,""(?i)terra""),""Terra"", IF( REGEXMATCH($B26,""(?i)desenvolvimento""),""Desenvolvimento"&""", IF( REGEXMATCH($B26,""(?i)remada""),""Remada"", IF(REGEXMATCH($B26,""(?i)arranco""),""Arranco"",IF(REGEXMATCH($B26,""(?i)arremesso""),""Arremesso"","""")) ) ) ) ) ), prs!$A$6:$D$12, 4, FALSE ) ,"""")"),"") | R26: =IFERROR(__xludf.DUMMYFUNCTION("IFERROR( $Q26/ VLOOKUP( IF( REGEXMATCH($B26,""(?i)agachamento""),""Agachamento"", IF( REGEXMATCH($B26,""(?i)supino""),""Supino"", IF( REGEXMATCH($B26,""(?i)terra""),""Terra"", IF( REGEXMATCH($B26,""(?i)desenvolvimento""),""Desenvolvimento"&""", IF( REGEXMATCH($B26,""(?i)remada""),""Remada"", IF(REGEXMATCH($B26,""(?i)arranco""),""Arranco"",IF(REGEXMATCH($B26,""(?i)arremesso""),""Arremesso"","""")) ) ) ) ) ), prs!$A$6:$D$12, 4, FALSE ) ,"""")"),"") | X26: =IFERROR(__xludf.DUMMYFUNCTION("IFERROR( $W26/ VLOOKUP( IF( REGEXMATCH($B26,""(?i)agachamento""),""Agachamento"", IF( REGEXMATCH($B26,""(?i)supino""),""Supino"", IF( REGEXMATCH($B26,""(?i)terra""),""Terra"", IF( REGEXMATCH($B26,""(?i)desenvolvimento""),""Desenvolvimento"&""", IF( REGEXMATCH($B26,""(?i)remada""),""Remada"", IF(REGEXMATCH($B26,""(?i)arranco""),""Arranco"",IF(REGEXMATCH($B26,""(?i)arremesso""),""Arremesso"","""")) ) ) ) ) ), prs!$A$6:$D$12, 4, FALSE ) ,"""")"),"")
F27: =IFERROR(__xludf.DUMMYFUNCTION("IFERROR( $E27/ VLOOKUP( IF( REGEXMATCH($B27,""(?i)agachamento""),""Agachamento"", IF( REGEXMATCH($B27,""(?i)supino""),""Supino"", IF( REGEXMATCH($B27,""(?i)terra""),""Terra"", IF( REGEXMATCH($B27,""(?i)desenvolvimento""),""Desenvolvimento"&""", IF( REGEXMATCH($B27,""(?i)remada""),""Remada"", IF(REGEXMATCH($B27,""(?i)arranco""),""Arranco"",IF(REGEXMATCH($B27,""(?i)arremesso""),""Arremesso"","""")) ) ) ) ) ), prs!$A$6:$D$12, 4, FALSE ) ,"""")"),"") | L27: =IFERROR(__xludf.DUMMYFUNCTION("IFERROR( $K27/ VLOOKUP( IF( REGEXMATCH($B27,""(?i)agachamento""),""Agachamento"", IF( REGEXMATCH($B27,""(?i)supino""),""Supino"", IF( REGEXMATCH($B27,""(?i)terra""),""Terra"", IF( REGEXMATCH($B27,""(?i)desenvolvimento""),""Desenvolvimento"&""", IF( REGEXMATCH($B27,""(?i)remada""),""Remada"", IF(REGEXMATCH($B27,""(?i)arranco""),""Arranco"",IF(REGEXMATCH($B27,""(?i)arremesso""),""Arremesso"","""")) ) ) ) ) ), prs!$A$6:$D$12, 4, FALSE ) ,"""")"),"") | R27: =IFERROR(__xludf.DUMMYFUNCTION("IFERROR( $Q27/ VLOOKUP( IF( REGEXMATCH($B27,""(?i)agachamento""),""Agachamento"", IF( REGEXMATCH($B27,""(?i)supino""),""Supino"", IF( REGEXMATCH($B27,""(?i)terra""),""Terra"", IF( REGEXMATCH($B27,""(?i)desenvolvimento""),""Desenvolvimento"&""", IF( REGEXMATCH($B27,""(?i)remada""),""Remada"", IF(REGEXMATCH($B27,""(?i)arranco""),""Arranco"",IF(REGEXMATCH($B27,""(?i)arremesso""),""Arremesso"","""")) ) ) ) ) ), prs!$A$6:$D$12, 4, FALSE ) ,"""")"),"") | X27: =IFERROR(__xludf.DUMMYFUNCTION("IFERROR( $W27/ VLOOKUP( IF( REGEXMATCH($B27,""(?i)agachamento""),""Agachamento"", IF( REGEXMATCH($B27,""(?i)supino""),""Supino"", IF( REGEXMATCH($B27,""(?i)terra""),""Terra"", IF( REGEXMATCH($B27,""(?i)desenvolvimento""),""Desenvolvimento"&""", IF( REGEXMATCH($B27,""(?i)remada""),""Remada"", IF(REGEXMATCH($B27,""(?i)arranco""),""Arranco"",IF(REGEXMATCH($B27,""(?i)arremesso""),""Arremesso"","""")) ) ) ) ) ), prs!$A$6:$D$12, 4, FALSE ) ,"""")"),"")
F28: =IFERROR(__xludf.DUMMYFUNCTION("IFERROR( $E28/ VLOOKUP( IF( REGEXMATCH($B28,""(?i)agachamento""),""Agachamento"", IF( REGEXMATCH($B28,""(?i)supino""),""Supino"", IF( REGEXMATCH($B28,""(?i)terra""),""Terra"", IF( REGEXMATCH($B28,""(?i)desenvolvimento""),""Desenvolvimento"&""", IF( REGEXMATCH($B28,""(?i)remada""),""Remada"", IF(REGEXMATCH($B28,""(?i)arranco""),""Arranco"",IF(REGEXMATCH($B28,""(?i)arremesso""),""Arremesso"","""")) ) ) ) ) ), prs!$A$6:$D$12, 4, FALSE ) ,"""")"),"") | L28: =IFERROR(__xludf.DUMMYFUNCTION("IFERROR( $K28/ VLOOKUP( IF( REGEXMATCH($B28,""(?i)agachamento""),""Agachamento"", IF( REGEXMATCH($B28,""(?i)supino""),""Supino"", IF( REGEXMATCH($B28,""(?i)terra""),""Terra"", IF( REGEXMATCH($B28,""(?i)desenvolvimento""),""Desenvolvimento"&""", IF( REGEXMATCH($B28,""(?i)remada""),""Remada"", IF(REGEXMATCH($B28,""(?i)arranco""),""Arranco"",IF(REGEXMATCH($B28,""(?i)arremesso""),""Arremesso"","""")) ) ) ) ) ), prs!$A$6:$D$12, 4, FALSE ) ,"""")"),"") | R28: =IFERROR(__xludf.DUMMYFUNCTION("IFERROR( $Q28/ VLOOKUP( IF( REGEXMATCH($B28,""(?i)agachamento""),""Agachamento"", IF( REGEXMATCH($B28,""(?i)supino""),""Supino"", IF( REGEXMATCH($B28,""(?i)terra""),""Terra"", IF( REGEXMATCH($B28,""(?i)desenvolvimento""),""Desenvolvimento"&""", IF( REGEXMATCH($B28,""(?i)remada""),""Remada"", IF(REGEXMATCH($B28,""(?i)arranco""),""Arranco"",IF(REGEXMATCH($B28,""(?i)arremesso""),""Arremesso"","""")) ) ) ) ) ), prs!$A$6:$D$12, 4, FALSE ) ,"""")"),"") | X28: =IFERROR(__xludf.DUMMYFUNCTION("IFERROR( $W28/ VLOOKUP( IF( REGEXMATCH($B28,""(?i)agachamento""),""Agachamento"", IF( REGEXMATCH($B28,""(?i)supino""),""Supino"", IF( REGEXMATCH($B28,""(?i)terra""),""Terra"", IF( REGEXMATCH($B28,""(?i)desenvolvimento""),""Desenvolvimento"&""", IF( REGEXMATCH($B28,""(?i)remada""),""Remada"", IF(REGEXMATCH($B28,""(?i)arranco""),""Arranco"",IF(REGEXMATCH($B28,""(?i)arremesso""),""Arremesso"","""")) ) ) ) ) ), prs!$A$6:$D$12, 4, FALSE ) ,"""")"),"")
F29: =IFERROR(__xludf.DUMMYFUNCTION("IFERROR( $E29/ VLOOKUP( IF( REGEXMATCH($B29,""(?i)agachamento""),""Agachamento"", IF( REGEXMATCH($B29,""(?i)supino""),""Supino"", IF( REGEXMATCH($B29,""(?i)terra""),""Terra"", IF( REGEXMATCH($B29,""(?i)desenvolvimento""),""Desenvolvimento"&""", IF( REGEXMATCH($B29,""(?i)remada""),""Remada"", IF(REGEXMATCH($B29,""(?i)arranco""),""Arranco"",IF(REGEXMATCH($B29,""(?i)arremesso""),""Arremesso"","""")) ) ) ) ) ), prs!$A$6:$D$12, 4, FALSE ) ,"""")"),"") | L29: =IFERROR(__xludf.DUMMYFUNCTION("IFERROR( $K29/ VLOOKUP( IF( REGEXMATCH($B29,""(?i)agachamento""),""Agachamento"", IF( REGEXMATCH($B29,""(?i)supino""),""Supino"", IF( REGEXMATCH($B29,""(?i)terra""),""Terra"", IF( REGEXMATCH($B29,""(?i)desenvolvimento""),""Desenvolvimento"&""", IF( REGEXMATCH($B29,""(?i)remada""),""Remada"", IF(REGEXMATCH($B29,""(?i)arranco""),""Arranco"",IF(REGEXMATCH($B29,""(?i)arremesso""),""Arremesso"","""")) ) ) ) ) ), prs!$A$6:$D$12, 4, FALSE ) ,"""")"),"") | R29: =IFERROR(__xludf.DUMMYFUNCTION("IFERROR( $Q29/ VLOOKUP( IF( REGEXMATCH($B29,""(?i)agachamento""),""Agachamento"", IF( REGEXMATCH($B29,""(?i)supino""),""Supino"", IF( REGEXMATCH($B29,""(?i)terra""),""Terra"", IF( REGEXMATCH($B29,""(?i)desenvolvimento""),""Desenvolvimento"&""", IF( REGEXMATCH($B29,""(?i)remada""),""Remada"", IF(REGEXMATCH($B29,""(?i)arranco""),""Arranco"",IF(REGEXMATCH($B29,""(?i)arremesso""),""Arremesso"","""")) ) ) ) ) ), prs!$A$6:$D$12, 4, FALSE ) ,"""")"),"") | X29: =IFERROR(__xludf.DUMMYFUNCTION("IFERROR( $W29/ VLOOKUP( IF( REGEXMATCH($B29,""(?i)agachamento""),""Agachamento"", IF( REGEXMATCH($B29,""(?i)supino""),""Supino"", IF( REGEXMATCH($B29,""(?i)terra""),""Terra"", IF( REGEXMATCH($B29,""(?i)desenvolvimento""),""Desenvolvimento"&""", IF( REGEXMATCH($B29,""(?i)remada""),""Remada"", IF(REGEXMATCH($B29,""(?i)arranco""),""Arranco"",IF(REGEXMATCH($B29,""(?i)arremesso""),""Arremesso"","""")) ) ) ) ) ), prs!$A$6:$D$12, 4, FALSE ) ,"""")"),"")
F30: =IFERROR(__xludf.DUMMYFUNCTION("IFERROR( $E30/ VLOOKUP( IF( REGEXMATCH($B30,""(?i)agachamento""),""Agachamento"", IF( REGEXMATCH($B30,""(?i)supino""),""Supino"", IF( REGEXMATCH($B30,""(?i)terra""),""Terra"", IF( REGEXMATCH($B30,""(?i)desenvolvimento""),""Desenvolvimento"&""", IF( REGEXMATCH($B30,""(?i)remada""),""Remada"", IF(REGEXMATCH($B30,""(?i)arranco""),""Arranco"",IF(REGEXMATCH($B30,""(?i)arremesso""),""Arremesso"","""")) ) ) ) ) ), prs!$A$6:$D$12, 4, FALSE ) ,"""")"),"") | L30: =IFERROR(__xludf.DUMMYFUNCTION("IFERROR( $K30/ VLOOKUP( IF( REGEXMATCH($B30,""(?i)agachamento""),""Agachamento"", IF( REGEXMATCH($B30,""(?i)supino""),""Supino"", IF( REGEXMATCH($B30,""(?i)terra""),""Terra"", IF( REGEXMATCH($B30,""(?i)desenvolvimento""),""Desenvolvimento"&""", IF( REGEXMATCH($B30,""(?i)remada""),""Remada"", IF(REGEXMATCH($B30,""(?i)arranco""),""Arranco"",IF(REGEXMATCH($B30,""(?i)arremesso""),""Arremesso"","""")) ) ) ) ) ), prs!$A$6:$D$12, 4, FALSE ) ,"""")"),"") | R30: =IFERROR(__xludf.DUMMYFUNCTION("IFERROR( $Q30/ VLOOKUP( IF( REGEXMATCH($B30,""(?i)agachamento""),""Agachamento"", IF( REGEXMATCH($B30,""(?i)supino""),""Supino"", IF( REGEXMATCH($B30,""(?i)terra""),""Terra"", IF( REGEXMATCH($B30,""(?i)desenvolvimento""),""Desenvolvimento"&""", IF( REGEXMATCH($B30,""(?i)remada""),""Remada"", IF(REGEXMATCH($B30,""(?i)arranco""),""Arranco"",IF(REGEXMATCH($B30,""(?i)arremesso""),""Arremesso"","""")) ) ) ) ) ), prs!$A$6:$D$12, 4, FALSE ) ,"""")"),"") | X30: =IFERROR(__xludf.DUMMYFUNCTION("IFERROR( $W30/ VLOOKUP( IF( REGEXMATCH($B30,""(?i)agachamento""),""Agachamento"", IF( REGEXMATCH($B30,""(?i)supino""),""Supino"", IF( REGEXMATCH($B30,""(?i)terra""),""Terra"", IF( REGEXMATCH($B30,""(?i)desenvolvimento""),""Desenvolvimento"&""", IF( REGEXMATCH($B30,""(?i)remada""),""Remada"", IF(REGEXMATCH($B30,""(?i)arranco""),""Arranco"",IF(REGEXMATCH($B30,""(?i)arremesso""),""Arremesso"","""")) ) ) ) ) ), prs!$A$6:$D$12, 4, FALSE ) ,"""")"),"")
C31: SEMANA 01 | I31: SEMANA 02 | O31: SEMANA 03 | U31: SEMANA 04
A33: TREINO 03
C34: SETS | D34: REPS | E34: KG | F34: %1RM | G34: OBS | I34: SETS | J34: REPS | K34: KG | L34: %1RM | M34: OBS | O34: SETS | P34: REPS | Q34: KG | R34: %1RM | S34: OBS | U34: SETS | V34: REPS | W34: KG | X34: %1RM | Y34: OBS
B35: exercícios | F35: pse | L35: pse | R35: pse | X35: pse
B36: Agachamento frontal | C36: 4 | D36: 5 | E36: 60 | F36: 0.5333 | L36: =IFERROR(__xludf.DUMMYFUNCTION("IFERROR( $K36/ VLOOKUP( IF( REGEXMATCH($B36,""(?i)agachamento""),""Agachamento"", IF( REGEXMATCH($B36,""(?i)supino""),""Supino"", IF( REGEXMATCH($B36,""(?i)terra""),""Terra"", IF( REGEXMATCH($B36,""(?i)desenvolvimento""),""Desenvolvimento"&""", IF( REGEXMATCH($B36,""(?i)remada""),""Remada"", IF(REGEXMATCH($B36,""(?i)arranco""),""Arranco"",IF(REGEXMATCH($B36,""(?i)arremesso""),""Arremesso"","""")) ) ) ) ) ), prs!$A$6:$D$12, 4, FALSE ) ,"""")"),"") | R36: =IFERROR(__xludf.DUMMYFUNCTION("IFERROR( $Q36/ VLOOKUP( IF( REGEXMATCH($B36,""(?i)agachamento""),""Agachamento"", IF( REGEXMATCH($B36,""(?i)supino""),""Supino"", IF( REGEXMATCH($B36,""(?i)terra""),""Terra"", IF( REGEXMATCH($B36,""(?i)desenvolvimento""),""Desenvolvimento"&""", IF( REGEXMATCH($B36,""(?i)remada""),""Remada"", IF(REGEXMATCH($B36,""(?i)arranco""),""Arranco"",IF(REGEXMATCH($B36,""(?i)arremesso""),""Arremesso"","""")) ) ) ) ) ), prs!$A$6:$D$12, 4, FALSE ) ,"""")"),"") | X36: =IFERROR(__xludf.DUMMYFUNCTION("IFERROR( $W36/ VLOOKUP( IF( REGEXMATCH($B36,""(?i)agachamento""),""Agachamento"", IF( REGEXMATCH($B36,""(?i)supino""),""Supino"", IF( REGEXMATCH($B36,""(?i)terra""),""Terra"", IF( REGEXMATCH($B36,""(?i)desenvolvimento""),""Desenvolvimento"&""", IF( REGEXMATCH($B36,""(?i)remada""),""Remada"", IF(REGEXMATCH($B36,""(?i)arranco""),""Arranco"",IF(REGEXMATCH($B36,""(?i)arremesso""),""Arremesso"","""")) ) ) ) ) ), prs!$A$6:$D$12, 4, FALSE ) ,"""")"),"")
B37: Supino inclinado | C37: 3 | D37: 8 | E37: 50 | F37: 0.6349 | L37: =IFERROR(__xludf.DUMMYFUNCTION("IFERROR( $K37/ VLOOKUP( IF( REGEXMATCH($B37,""(?i)agachamento""),""Agachamento"", IF( REGEXMATCH($B37,""(?i)supino""),""Supino"", IF( REGEXMATCH($B37,""(?i)terra""),""Terra"", IF( REGEXMATCH($B37,""(?i)desenvolvimento""),""Desenvolvimento"&""", IF( REGEXMATCH($B37,""(?i)remada""),""Remada"", IF(REGEXMATCH($B37,""(?i)arranco""),""Arranco"",IF(REGEXMATCH($B37,""(?i)arremesso""),""Arremesso"","""")) ) ) ) ) ), prs!$A$6:$D$12, 4, FALSE ) ,"""")"),"") | R37: =IFERROR(__xludf.DUMMYFUNCTION("IFERROR( $Q37/ VLOOKUP( IF( REGEXMATCH($B37,""(?i)agachamento""),""Agachamento"", IF( REGEXMATCH($B37,""(?i)supino""),""Supino"", IF( REGEXMATCH($B37,""(?i)terra""),""Terra"", IF( REGEXMATCH($B37,""(?i)desenvolvimento""),""Desenvolvimento"&""", IF( REGEXMATCH($B37,""(?i)remada""),""Remada"", IF(REGEXMATCH($B37,""(?i)arranco""),""Arranco"",IF(REGEXMATCH($B37,""(?i)arremesso""),""Arremesso"","""")) ) ) ) ) ), prs!$A$6:$D$12, 4, FALSE ) ,"""")"),"") | X37: =IFERROR(__xludf.DUMMYFUNCTION("IFERROR( $W37/ VLOOKUP( IF( REGEXMATCH($B37,""(?i)agachamento""),""Agachamento"", IF( REGEXMATCH($B37,""(?i)supino""),""Supino"", IF( REGEXMATCH($B37,""(?i)terra""),""Terra"", IF( REGEXMATCH($B37,""(?i)desenvolvimento""),""Desenvolvimento"&""", IF( REGEXMATCH($B37,""(?i)remada""),""Remada"", IF(REGEXMATCH($B37,""(?i)arranco""),""Arranco"",IF(REGEXMATCH($B37,""(?i)arremesso""),""Arremesso"","""")) ) ) ) ) ), prs!$A$6:$D$12, 4, FALSE ) ,"""")"),"")
B38: Barra fixa | C38: 3 | D38: AMRAP | G38: amrap | L38: =IFERROR(__xludf.DUMMYFUNCTION("IFERROR( $K38/ VLOOKUP( IF( REGEXMATCH($B38,""(?i)agachamento""),""Agachamento"", IF( REGEXMATCH($B38,""(?i)supino""),""Supino"", IF( REGEXMATCH($B38,""(?i)terra""),""Terra"", IF( REGEXMATCH($B38,""(?i)desenvolvimento""),""Desenvolvimento"&""", IF( REGEXMATCH($B38,""(?i)remada""),""Remada"", IF(REGEXMATCH($B38,""(?i)arranco""),""Arranco"",IF(REGEXMATCH($B38,""(?i)arremesso""),""Arremesso"","""")) ) ) ) ) ), prs!$A$6:$D$12, 4, FALSE ) ,"""")"),"") | R38: =IFERROR(__xludf.DUMMYFUNCTION("IFERROR( $Q38/ VLOOKUP( IF( REGEXMATCH($B38,""(?i)agachamento""),""Agachamento"", IF( REGEXMATCH($B38,""(?i)supino""),""Supino"", IF( REGEXMATCH($B38,""(?i)terra""),""Terra"", IF( REGEXMATCH($B38,""(?i)desenvolvimento""),""Desenvolvimento"&""", IF( REGEXMATCH($B38,""(?i)remada""),""Remada"", IF(REGEXMATCH($B38,""(?i)arranco""),""Arranco"",IF(REGEXMATCH($B38,""(?i)arremesso""),""Arremesso"","""")) ) ) ) ) ), prs!$A$6:$D$12, 4, FALSE ) ,"""")"),"") | X38: =IFERROR(__xludf.DUMMYFUNCTION("IFERROR( $W38/ VLOOKUP( IF( REGEXMATCH($B38,""(?i)agachamento""),""Agachamento"", IF( REGEXMATCH($B38,""(?i)supino""),""Supino"", IF( REGEXMATCH($B38,""(?i)terra""),""Terra"", IF( REGEXMATCH($B38,""(?i)desenvolvimento""),""Desenvolvimento"&""", IF( REGEXMATCH($B38,""(?i)remada""),""Remada"", IF(REGEXMATCH($B38,""(?i)arranco""),""Arranco"",IF(REGEXMATCH($B38,""(?i)arremesso""),""Arremesso"","""")) ) ) ) ) ), prs!$A$6:$D$12, 4, FALSE ) ,"""")"),"")
B39: Elevação pélvica | C39: 3 | D39: 12 | E39: 60 | L39: =IFERROR(__xludf.DUMMYFUNCTION("IFERROR( $K39/ VLOOKUP( IF( REGEXMATCH($B39,""(?i)agachamento""),""Agachamento"", IF( REGEXMATCH($B39,""(?i)supino""),""Supino"", IF( REGEXMATCH($B39,""(?i)terra""),""Terra"", IF( REGEXMATCH($B39,""(?i)desenvolvimento""),""Desenvolvimento"&""", IF( REGEXMATCH($B39,""(?i)remada""),""Remada"", IF(REGEXMATCH($B39,""(?i)arranco""),""Arranco"",IF(REGEXMATCH($B39,""(?i)arremesso""),""Arremesso"","""")) ) ) ) ) ), prs!$A$6:$D$12, 4, FALSE ) ,"""")"),"") | R39: =IFERROR(__xludf.DUMMYFUNCTION("IFERROR( $Q39/ VLOOKUP( IF( REGEXMATCH($B39,""(?i)agachamento""),""Agachamento"", IF( REGEXMATCH($B39,""(?i)supino""),""Supino"", IF( REGEXMATCH($B39,""(?i)terra""),""Terra"", IF( REGEXMATCH($B39,""(?i)desenvolvimento""),""Desenvolvimento"&""", IF( REGEXMATCH($B39,""(?i)remada""),""Remada"", IF(REGEXMATCH($B39,""(?i)arranco""),""Arranco"",IF(REGEXMATCH($B39,""(?i)arremesso""),""Arremesso"","""")) ) ) ) ) ), prs!$A$6:$D$12, 4, FALSE ) ,"""")"),"") | X39: =IFERROR(__xludf.DUMMYFUNCTION("IFERROR( $W39/ VLOOKUP( IF( REGEXMATCH($B39,""(?i)agachamento""),""Agachamento"", IF( REGEXMATCH($B39,""(?i)supino""),""Supino"", IF( REGEXMATCH($B39,""(?i)terra""),""Terra"", IF( REGEXMATCH($B39,""(?i)desenvolvimento""),""Desenvolvimento"&""", IF( REGEXMATCH($B39,""(?i)remada""),""Remada"", IF(REGEXMATCH($B39,""(?i)arranco""),""Arranco"",IF(REGEXMATCH($B39,""(?i)arremesso""),""Arremesso"","""")) ) ) ) ) ), prs!$A$6:$D$12, 4, FALSE ) ,"""")"),"")
F40: =IFERROR(__xludf.DUMMYFUNCTION("IFERROR( $E40/ VLOOKUP( IF( REGEXMATCH($B40,""(?i)agachamento""),""Agachamento"", IF( REGEXMATCH($B40,""(?i)supino""),""Supino"", IF( REGEXMATCH($B40,""(?i)terra""),""Terra"", IF( REGEXMATCH($B40,""(?i)desenvolvimento""),""Desenvolvimento"&""", IF( REGEXMATCH($B40,""(?i)remada""),""Remada"", IF(REGEXMATCH($B40,""(?i)arranco""),""Arranco"",IF(REGEXMATCH($B40,""(?i)arremesso""),""Arremesso"","""")) ) ) ) ) ), prs!$A$6:$D$12, 4, FALSE ) ,"""")"),"") | L40: =IFERROR(__xludf.DUMMYFUNCTION("IFERROR( $K40/ VLOOKUP( IF( REGEXMATCH($B40,""(?i)agachamento""),""Agachamento"", IF( REGEXMATCH($B40,""(?i)supino""),""Supino"", IF( REGEXMATCH($B40,""(?i)terra""),""Terra"", IF( REGEXMATCH($B40,""(?i)desenvolvimento""),""Desenvolvimento"&""", IF( REGEXMATCH($B40,""(?i)remada""),""Remada"", IF(REGEXMATCH($B40,""(?i)arranco""),""Arranco"",IF(REGEXMATCH($B40,""(?i)arremesso""),""Arremesso"","""")) ) ) ) ) ), prs!$A$6:$D$12, 4, FALSE ) ,"""")"),"") | R40: =IFERROR(__xludf.DUMMYFUNCTION("IFERROR( $Q40/ VLOOKUP( IF( REGEXMATCH($B40,""(?i)agachamento""),""Agachamento"", IF( REGEXMATCH($B40,""(?i)supino""),""Supino"", IF( REGEXMATCH($B40,""(?i)terra""),""Terra"", IF( REGEXMATCH($B40,""(?i)desenvolvimento""),""Desenvolvimento"&""", IF( REGEXMATCH($B40,""(?i)remada""),""Remada"", IF(REGEXMATCH($B40,""(?i)arranco""),""Arranco"",IF(REGEXMATCH($B40,""(?i)arremesso""),""Arremesso"","""")) ) ) ) ) ), prs!$A$6:$D$12, 4, FALSE ) ,"""")"),"") | X40: =IFERROR(__xludf.DUMMYFUNCTION("IFERROR( $W40/ VLOOKUP( IF( REGEXMATCH($B40,""(?i)agachamento""),""Agachamento"", IF( REGEXMATCH($B40,""(?i)supino""),""Supino"", IF( REGEXMATCH($B40,""(?i)terra""),""Terra"", IF( REGEXMATCH($B40,""(?i)desenvolvimento""),""Desenvolvimento"&""", IF( REGEXMATCH($B40,""(?i)remada""),""Remada"", IF(REGEXMATCH($B40,""(?i)arranco""),""Arranco"",IF(REGEXMATCH($B40,""(?i)arremesso""),""Arremesso"","""")) ) ) ) ) ), prs!$A$6:$D$12, 4, FALSE ) ,"""")"),"")
F41: =IFERROR(__xludf.DUMMYFUNCTION("IFERROR( $E41/ VLOOKUP( IF( REGEXMATCH($B41,""(?i)agachamento""),""Agachamento"", IF( REGEXMATCH($B41,""(?i)supino""),""Supino"", IF( REGEXMATCH($B41,""(?i)terra""),""Terra"", IF( REGEXMATCH($B41,""(?i)desenvolvimento""),""Desenvolvimento"&""", IF( REGEXMATCH($B41,""(?i)remada""),""Remada"", IF(REGEXMATCH($B41,""(?i)arranco""),""Arranco"",IF(REGEXMATCH($B41,""(?i)arremesso""),""Arremesso"","""")) ) ) ) ) ), prs!$A$6:$D$12, 4, FALSE ) ,"""")"),"") | L41: =IFERROR(__xludf.DUMMYFUNCTION("IFERROR( $K41/ VLOOKUP( IF( REGEXMATCH($B41,""(?i)agachamento""),""Agachamento"", IF( REGEXMATCH($B41,""(?i)supino""),""Supino"", IF( REGEXMATCH($B41,""(?i)terra""),""Terra"", IF( REGEXMATCH($B41,""(?i)desenvolvimento""),""Desenvolvimento"&""", IF( REGEXMATCH($B41,""(?i)remada""),""Remada"", IF(REGEXMATCH($B41,""(?i)arranco""),""Arranco"",IF(REGEXMATCH($B41,""(?i)arremesso""),""Arremesso"","""")) ) ) ) ) ), prs!$A$6:$D$12, 4, FALSE ) ,"""")"),"") | R41: =IFERROR(__xludf.DUMMYFUNCTION("IFERROR( $Q41/ VLOOKUP( IF( REGEXMATCH($B41,""(?i)agachamento""),""Agachamento"", IF( REGEXMATCH($B41,""(?i)supino""),""Supino"", IF( REGEXMATCH($B41,""(?i)terra""),""Terra"", IF( REGEXMATCH($B41,""(?i)desenvolvimento""),""Desenvolvimento"&""", IF( REGEXMATCH($B41,""(?i)remada""),""Remada"", IF(REGEXMATCH($B41,""(?i)arranco""),""Arranco"",IF(REGEXMATCH($B41,""(?i)arremesso""),""Arremesso"","""")) ) ) ) ) ), prs!$A$6:$D$12, 4, FALSE ) ,"""")"),"") | X41: =IFERROR(__xludf.DUMMYFUNCTION("IFERROR( $W41/ VLOOKUP( IF( REGEXMATCH($B41,""(?i)agachamento""),""Agachamento"", IF( REGEXMATCH($B41,""(?i)supino""),""Supino"", IF( REGEXMATCH($B41,""(?i)terra""),""Terra"", IF( REGEXMATCH($B41,""(?i)desenvolvimento""),""Desenvolvimento"&""", IF( REGEXMATCH($B41,""(?i)remada""),""Remada"", IF(REGEXMATCH($B41,""(?i)arranco""),""Arranco"",IF(REGEXMATCH($B41,""(?i)arremesso""),""Arremesso"","""")) ) ) ) ) ), prs!$A$6:$D$12, 4, FALSE ) ,"""")"),"")
F42: =IFERROR(__xludf.DUMMYFUNCTION("IFERROR( $E42/ VLOOKUP( IF( REGEXMATCH($B42,""(?i)agachamento""),""Agachamento"", IF( REGEXMATCH($B42,""(?i)supino""),""Supino"", IF( REGEXMATCH($B42,""(?i)terra""),""Terra"", IF( REGEXMATCH($B42,""(?i)desenvolvimento""),""Desenvolvimento"&""", IF( REGEXMATCH($B42,""(?i)remada""),""Remada"", IF(REGEXMATCH($B42,""(?i)arranco""),""Arranco"",IF(REGEXMATCH($B42,""(?i)arremesso""),""Arremesso"","""")) ) ) ) ) ), prs!$A$6:$D$12, 4, FALSE ) ,"""")"),"") | L42: =IFERROR(__xludf.DUMMYFUNCTION("IFERROR( $K42/ VLOOKUP( IF( REGEXMATCH($B42,""(?i)agachamento""),""Agachamento"", IF( REGEXMATCH($B42,""(?i)supino""),""Supino"", IF( REGEXMATCH($B42,""(?i)terra""),""Terra"", IF( REGEXMATCH($B42,""(?i)desenvolvimento""),""Desenvolvimento"&""", IF( REGEXMATCH($B42,""(?i)remada""),""Remada"", IF(REGEXMATCH($B42,""(?i)arranco""),""Arranco"",IF(REGEXMATCH($B42,""(?i)arremesso""),""Arremesso"","""")) ) ) ) ) ), prs!$A$6:$D$12, 4, FALSE ) ,"""")"),"") | R42: =IFERROR(__xludf.DUMMYFUNCTION("IFERROR( $Q42/ VLOOKUP( IF( REGEXMATCH($B42,""(?i)agachamento""),""Agachamento"", IF( REGEXMATCH($B42,""(?i)supino""),""Supino"", IF( REGEXMATCH($B42,""(?i)terra""),""Terra"", IF( REGEXMATCH($B42,""(?i)desenvolvimento""),""Desenvolvimento"&""", IF( REGEXMATCH($B42,""(?i)remada""),""Remada"", IF(REGEXMATCH($B42,""(?i)arranco""),""Arranco"",IF(REGEXMATCH($B42,""(?i)arremesso""),""Arremesso"","""")) ) ) ) ) ), prs!$A$6:$D$12, 4, FALSE ) ,"""")"),"") | X42: =IFERROR(__xludf.DUMMYFUNCTION("IFERROR( $W42/ VLOOKUP( IF( REGEXMATCH($B42,""(?i)agachamento""),""Agachamento"", IF( REGEXMATCH($B42,""(?i)supino""),""Supino"", IF( REGEXMATCH($B42,""(?i)terra""),""Terra"", IF( REGEXMATCH($B42,""(?i)desenvolvimento""),""Desenvolvimento"&""", IF( REGEXMATCH($B42,""(?i)remada""),""Remada"", IF(REGEXMATCH($B42,""(?i)arranco""),""Arranco"",IF(REGEXMATCH($B42,""(?i)arremesso""),""Arremesso"","""")) ) ) ) ) ), prs!$A$6:$D$12, 4, FALSE ) ,"""")"),"")
F43: =IFERROR(__xludf.DUMMYFUNCTION("IFERROR( $E43/ VLOOKUP( IF( REGEXMATCH($B43,""(?i)agachamento""),""Agachamento"", IF( REGEXMATCH($B43,""(?i)supino""),""Supino"", IF( REGEXMATCH($B43,""(?i)terra""),""Terra"", IF( REGEXMATCH($B43,""(?i)desenvolvimento""),""Desenvolvimento"&""", IF( REGEXMATCH($B43,""(?i)remada""),""Remada"", IF(REGEXMATCH($B43,""(?i)arranco""),""Arranco"",IF(REGEXMATCH($B43,""(?i)arremesso""),""Arremesso"","""")) ) ) ) ) ), prs!$A$6:$D$12, 4, FALSE ) ,"""")"),"") | L43: =IFERROR(__xludf.DUMMYFUNCTION("IFERROR( $K43/ VLOOKUP( IF( REGEXMATCH($B43,""(?i)agachamento""),""Agachamento"", IF( REGEXMATCH($B43,""(?i)supino""),""Supino"", IF( REGEXMATCH($B43,""(?i)terra""),""Terra"", IF( REGEXMATCH($B43,""(?i)desenvolvimento""),""Desenvolvimento"&""", IF( REGEXMATCH($B43,""(?i)remada""),""Remada"", IF(REGEXMATCH($B43,""(?i)arranco""),""Arranco"",IF(REGEXMATCH($B43,""(?i)arremesso""),""Arremesso"","""")) ) ) ) ) ), prs!$A$6:$D$12, 4, FALSE ) ,"""")"),"") | R43: =IFERROR(__xludf.DUMMYFUNCTION("IFERROR( $Q43/ VLOOKUP( IF( REGEXMATCH($B43,""(?i)agachamento""),""Agachamento"", IF( REGEXMATCH($B43,""(?i)supino""),""Supino"", IF( REGEXMATCH($B43,""(?i)terra""),""Terra"", IF( REGEXMATCH($B43,""(?i)desenvolvimento""),""Desenvolvimento"&""", IF( REGEXMATCH($B43,""(?i)remada""),""Remada"", IF(REGEXMATCH($B43,""(?i)arranco""),""Arranco"",IF(REGEXMATCH($B43,""(?i)arremesso""),""Arremesso"","""")) ) ) ) ) ), prs!$A$6:$D$12, 4, FALSE ) ,"""")"),"") | X43: =IFERROR(__xludf.DUMMYFUNCTION("IFERROR( $W43/ VLOOKUP( IF( REGEXMATCH($B43,""(?i)agachamento""),""Agachamento"", IF( REGEXMATCH($B43,""(?i)supino""),""Supino"", IF( REGEXMATCH($B43,""(?i)terra""),""Terra"", IF( REGEXMATCH($B43,""(?i)desenvolvimento""),""Desenvolvimento"&""", IF( REGEXMATCH($B43,""(?i)remada""),""Remada"", IF(REGEXMATCH($B43,""(?i)arranco""),""Arranco"",IF(REGEXMATCH($B43,""(?i)arremesso""),""Arremesso"","""")) ) ) ) ) ), prs!$A$6:$D$12, 4, FALSE ) ,"""")"),"")
...

Sheet aluno 02
B1: PLANILHA DE TREINAMENTO
B2: NOME | C2: ='aluno 01'!C2
B3: OBJETIVO | C3: ='aluno 01'!C3
B5: SEGUNDA | C5: TERÇA | D5: QUARTA | E5: QUINTA | F5: SEXTA
B6: ='aluno 01'!B6 | C6: ='aluno 01'!C6 | D6: ='aluno 01'!D6 | E6: ='aluno 01'!E6 | F6: ='aluno 01'!F6
A8: OBS
A9: ='aluno 01'!A9
A11: AQC
B12: SETS | C12: REPS / TEMPO | D12: KG | E12: OBS
A16: ='bloco 02'!C3
A17: SEMANA 01
A18: TREINO 01
B19: SETS | C19: REPS | D19: KG | E19: %1RM / PSE | F19: OBS
A20: ='bloco 02'!$B6 | B20: ='bloco 02'!C6 | C20: ='bloco 02'!D6 | D20: ='bloco 02'!E6 | E20: =IFERROR(('bloco 02'!F6),"") | F20: ='bloco 02'!G6
A21: ='bloco 02'!$B7 | B21: ='bloco 02'!C7 | C21: ='bloco 02'!D7 | D21: ='bloco 02'!E7 | E21: =IFERROR(('bloco 02'!F7),"") | F21: ='bloco 02'!G7
A22: ='bloco 02'!$B8 | B22: ='bloco 02'!C8 | C22: ='bloco 02'!D8 | D22: ='bloco 02'!E8 | E22: =IFERROR(('bloco 02'!F8),"") | F22: ='bloco 02'!G8
A23: ='bloco 02'!$B9 | B23: ='bloco 02'!C9 | C23: ='bloco 02'!D9 | D23: ='bloco 02'!E9 | E23: =IFERROR(('bloco 02'!F9),"") | F23: ='bloco 02'!G9
A24: ='bloco 02'!$B10 | B24: ='bloco 02'!C10 | C24: ='bloco 02'!D10 | D24: ='bloco 02'!E10 | E24: =IFERROR(('bloco 02'!F10),"") | F24: ='bloco 02'!G10
A25: ='bloco 02'!$B11 | B25: ='bloco 02'!C11 | C25: ='bloco 02'!D11 | D25: ='bloco 02'!E11 | E25: =IFERROR(('bloco 02'!F11),"") | F25: ='bloco 02'!G11
A26: ='bloco 02'!$B12 | B26: ='bloco 02'!C12 | C26: ='bloco 02'!D12 | D26: ='bloco 02'!E12 | E26: =IFERROR(('bloco 02'!F12),"") | F26: ='bloco 02'!G12
A27: ='bloco 02'!$B13 | B27: ='bloco 02'!C13 | C27: ='bloco 02'!D13 | D27: ='bloco 02'!E13 | E27: =IFERROR(('bloco 02'!F13),"") | F27: ='bloco 02'!G13
A28: ='bloco 02'!$B14 | B28: ='bloco 02'!C14 | C28: ='bloco 02'!D14 | D28: ='bloco 02'!E14 | E28: =IFERROR(('bloco 02'!F14),"") | F28: ='bloco 02'!G14
A29: ='bloco 02'!$B15 | B29: ='bloco 02'!C15 | C29: ='bloco 02'!D15 | D29: ='bloco 02'!E15 | E29: =IFERROR(('bloco 02'!F15),"") | F29: ='bloco 02'!G15
A30: TREINO 02
B31: SETS | C31: REPS | D31: KG | E31: %1RM / PSE | F31: OBS
A32: ='bloco 02'!$B21 | B32: ='bloco 02'!C21 | C32: ='bloco 02'!D21 | D32: ='bloco 02'!E21 | E32: =IFERROR(('bloco 02'!F21),"") | F32: ='bloco 02'!G21
A33: ='bloco 02'!$B22 | B33: ='bloco 02'!C22 | C33: ='bloco 02'!D22 | D33: ='bloco 02'!E22 | E33: =IFERROR(('bloco 02'!F22),"") | F33: ='bloco 02'!G22
A34: ='bloco 02'!$B23 | B34: ='bloco 02'!C23 | C34: ='bloco 02'!D23 | D34: ='bloco 02'!E23 | E34: =IFERROR(('bloco 02'!F23),"") | F34: ='bloco 02'!G23
A35: ='bloco 02'!$B24 | B35: ='bloco 02'!C24 | C35: ='bloco 02'!D24 | D35: ='bloco 02'!E24 | E35: =IFERROR(('bloco 02'!F24),"") | F35: ='bloco 02'!G24
A36: ='bloco 02'!$B25 | B36: ='bloco 02'!C25 | C36: ='bloco 02'!D25 | D36: ='bloco 02'!E25 | E36: =IFERROR(('bloco 02'!F25),"") | F36: ='bloco 02'!G25
A37: ='bloco 02'!$B26 | B37: ='bloco 02'!C26 | C37: ='bloco 02'!D26 | D37: ='bloco 02'!E26 | E37: =IFERROR(('bloco 02'!F26),"") | F37: ='bloco 02'!G26
A38: ='bloco 02'!$B27 | B38: ='bloco 02'!C27 | C38: ='bloco 02'!D27 | D38: ='bloco 02'!E27 | E38: =IFERROR(('bloco 02'!F27),"") | F38: ='bloco 02'!G27
A39: ='bloco 02'!$B28 | B39: ='bloco 02'!C28 | C39: ='bloco 02'!D28 | D39: ='bloco 02'!E28 | E39: =IFERROR(('bloco 02'!F28),"") | F39: ='bloco 02'!G28
A40: ='bloco 02'!$B29 | B40: ='bloco 02'!C29 | C40: ='bloco 02'!D29 | D40: ='bloco 02'!E29 | E40: =IFERROR(('bloco 02'!F29),"") | F40: ='bloco 02'!G29
A41: ='bloco 02'!$B30 | B41: ='bloco 02'!C30 | C41: ='bloco 02'!D30 | D41: ='bloco 02'!E30 | E41: =IFERROR(('bloco 02'!F30),"") | F41: ='bloco 02'!G30
A42: TREINO 03
B43: SETS | C43: REPS | D43: KG | E43: %1RM / PSE | F43: OBS
A44: ='bloco 02'!$B36 | B44: ='bloco 02'!C36 | C44: ='bloco 02'!D36 | D44: ='bloco 02'!E36 | E44: =IFERROR(('bloco 02'!F36),"") | F44: ='bloco 02'!G36
A45: ='bloco 02'!$B37 | B45: ='bloco 02'!C37 | C45: ='bloco 02'!D37 | D45: ='bloco 02'!E37 | E45: =IFERROR(('bloco 02'!F37),"") | F45: ='bloco 02'!G37
A46: ='bloco 02'!$B38 | B46: ='bloco 02'!C38 | C46: ='bloco 02'!D38 | D46: ='bloco 02'!E38 | E46: =IFERROR(('bloco 02'!F38),"") | F46: ='bloco 02'!G38
...

Sheet bloco 02
A1: BLOCO 02
A3: TREINO 01 | C3: =macro!F6 | I3: =C3+7 | O3: =I3+7 | U3: =O3+7
C4: SETS | D4: REPS | E4: KG | F4: %1RM | G4: OBS | I4: SETS | J4: REPS | K4: KG | L4: %1RM | M4: OBS | O4: SETS | P4: REPS | Q4: KG | R4: %1RM | S4: OBS | U4: SETS | V4: REPS | W4: KG | X4: %1RM | Y4: OBS
B5: exercícios | F5: pse | L5: pse | R5: pse | X5: pse
