Workbook

Sheet início
B1: FORÇA & INTELIGÊNCIA
B2: ='aluno 01'!C2
B4: OBJETIVO | E4: HOJE
B5: ='aluno 01'!C3 | E5: =IF(COUNT(macro!B6:M6)=0,"",IF(TODAY()<macro!B6,"Começa em "&TEXT(macro!B6,"dd/mm"),"Semana "&TEXT(MIN(COUNT(macro!B6:M6),MATCH(TODAY(),macro!B6:M6)),"00")))
B7: BLOCOS
C8: INÍCIO | D8: FIM
B9: Bloco 01 | C9: =macro!B6 | D9: =macro!B6+27 | E9: =IF(macro!B6="","",IF(TODAY()<macro!B6,"próximo",IF(TODAY()<=macro!B6+27,"em andamento","concluído")))
B10: Bloco 02 | C10: =macro!F6 | D10: =macro!F6+27 | E10: =IF(macro!F6="","",IF(TODAY()<macro!F6,"próximo",IF(TODAY()<=macro!F6+27,"em andamento","concluído")))
B11: Bloco 03 | C11: =macro!J6 | D11: =macro!J6+27 | E11: =IF(macro!J6="","",IF(TODAY()<macro!J6,"próximo",IF(TODAY()<=macro!J6+27,"em andamento","concluído")))
B13: 1RM ESTIMADO (KG)
C14: BLOCO 01 | D14: BLOCO 02 | E14: BLOCO 03
B15: Agachamento | C15: =IF(N(prs!D6)>0,ROUND(prs!D6),"") | D15: =IF(N(prs!D18)>0,ROUND(prs!D18),"") | E15: =IF(N(prs!D30)>0,ROUND(prs!D30),"")
B16: Supino | C16: =IF(N(prs!D7)>0,ROUND(prs!D7),"") | D16: =IF(N(prs!D19)>0,ROUND(prs!D19),"") | E16: =IF(N(prs!D31)>0,ROUND(prs!D31),"")
B17: Terra | C17: =IF(N(prs!D8)>0,ROUND(prs!D8),"") | D17: =IF(N(prs!D20)>0,ROUND(prs!D20),"") | E17: =IF(N(prs!D32)>0,ROUND(prs!D32),"")
B18: Desenvolvimento | C18: =IF(N(prs!D9)>0,ROUND(prs!D9),"") | D18: =IF(N(prs!D21)>0,ROUND(prs!D21),"") | E18: =IF(N(prs!D33)>0,ROUND(prs!D33),"")
B19: Remada | C19: =IF(N(prs!D10)>0,ROUND(prs!D10),"") | D19: =IF(N(prs!D22)>0,ROUND(prs!D22),"") | E19: =IF(N(prs!D34)>0,ROUND(prs!D34),"")
B20: Arranco | C20: =IF(N(prs!D11)>0,ROUND(prs!D11),"") | D20: =IF(N(prs!D23)>0,ROUND(prs!D23),"") | E20: =IF(N(prs!D35)>0,ROUND(prs!D35),"")
B21: Arremesso | C21: =IF(N(prs!D12)>0,ROUND(prs!D12),"") | D21: =IF(N(prs!D24)>0,ROUND(prs!D24),"") | E21: =IF(N(prs!D36)>0,ROUND(prs!D36),"")
B23: KG POR SEMANA
B24: =IFERROR(__xludf.DUMMYFUNCTION("SPARKLINE(macro!B3:M3,{""charttype"",""column"";""color"",""black"";""empty"",""zero""})"),"")

Sheet aluno 01
B1: PLANILHA DE TREINAMENTO
B2: NOME
B3: OBJETIVO
B5: SEGUNDA | C5: TERÇA | D5: QUARTA | E5: QUINTA | F5: SEXTA
A8: OBS
A11: AQC
B12: SETS | C12: REPS / TEMPO | D12: KG | E12: OBS
A16: ='bloco 01'!C3
A17: SEMANA 01
A18: TREINO 01
B19: SETS | C19: REPS | D19: KG | E19: %1RM / PSE | F19: OBS
A20: ='bloco 01'!$B$6 | B20: ='bloco 01'!C6 | C20: ='bloco 01'!D6 | D20: ='bloco 01'!E6 | E20: =IFERROR(('bloco 01'!F6),"") | F20: ='bloco 01'!G6
A21: ='bloco 01'!$B$7 | B21: ='bloco 01'!C7 | C21: ='bloco 01'!D7 | D21: ='bloco 01'!E7 | E21: =IFERROR(('bloco 01'!F7),"") | F21: ='bloco 01'!G7
A22: ='bloco 01'!$B$8 | B22: ='bloco 01'!C8 | C22: ='bloco 01'!D8 | D22: ='bloco 01'!E8 | E22: =IFERROR(('bloco 01'!F8),"") | F22: ='bloco 01'!G8
A23: ='bloco 01'!$B$9 | B23: ='bloco 01'!C9 | C23: ='bloco 01'!D9 | D23: ='bloco 01'!E9 | E23: =IFERROR(('bloco 01'!F9),"") | F23: ='bloco 01'!G9
A24: ='bloco 01'!$B$10 | B24: ='bloco 01'!C10 | C24: ='bloco 01'!D10 | D24: ='bloco 01'!E10 | E24: =IFERROR(('bloco 01'!F10),"") | F24: ='bloco 01'!G10
A25: ='bloco 01'!$B$11 | B25: ='bloco 01'!C11 | C25: ='bloco 01'!D11 | D25: ='bloco 01'!E11 | E25: =IFERROR(('bloco 01'!F11),"") | F25: ='bloco 01'!G11
A26: ='bloco 01'!$B$12 | B26: ='bloco 01'!C12 | C26: ='bloco 01'!D12 | D26: ='bloco 01'!E12 | E26: =IFERROR(('bloco 01'!F12),"") | F26: ='bloco 01'!G12
A27: ='bloco 01'!$B$13 | B27: ='bloco 01'!C13 | C27: ='bloco 01'!D13 | D27: ='bloco 01'!E13 | E27: =IFERROR(('bloco 01'!F13),"") | F27: ='bloco 01'!G13
A28: ='bloco 01'!$B$14 | B28: ='bloco 01'!C14 | C28: ='bloco 01'!D14 | D28: ='bloco 01'!E14 | E28: =IFERROR(('bloco 01'!F14),"") | F28: ='bloco 01'!G14
A29: ='bloco 01'!$B$15 | B29: ='bloco 01'!C15 | C29: ='bloco 01'!D15 | D29: ='bloco 01'!E15 | E29: =IFERROR(('bloco 01'!F15),"") | F29: ='bloco 01'!G15
A30: TREINO 02
B31: SETS | C31: REPS | D31: KG | E31: %1RM / PSE | F31: OBS
A32: ='bloco 01'!$B$21 | B32: ='bloco 01'!C21 | C32: ='bloco 01'!D21 | D32: ='bloco 01'!E21 | E32: =IFERROR(('bloco 01'!F21),"") | F32: ='bloco 01'!G21
A33: ='bloco 01'!$B$22 | B33: ='bloco 01'!C22 | C33: ='bloco 01'!D22 | D33: ='bloco 01'!E22 | E33: =IFERROR(('bloco 01'!F22),"") | F33: ='bloco 01'!G22
A34: ='bloco 01'!$B$23 | B34: ='bloco 01'!C23 | C34: ='bloco 01'!D23 | D34: ='bloco 01'!E23 | E34: =IFERROR(('bloco 01'!F23),"") | F34: ='bloco 01'!G23
A35: ='bloco 01'!$B$24 | B35: ='bloco 01'!C24 | C35: ='bloco 01'!D24 | D35: ='bloco 01'!E24 | E35: =IFERROR(('bloco 01'!F24),"") | F35: ='bloco 01'!G24
A36: ='bloco 01'!$B$25 | B36: ='bloco 01'!C25 | C36: ='bloco 01'!D25 | D36: ='bloco 01'!E25 | E36: =IFERROR(('bloco 01'!F25),"") | F36: ='bloco 01'!G25
A37: ='bloco 01'!$B$26 | B37: ='bloco 01'!C26 | C37: ='bloco 01'!D26 | D37: ='bloco 01'!E26 | E37: =IFERROR(('bloco 01'!F26),"") | F37: ='bloco 01'!G26
A38: ='bloco 01'!$B$27 | B38: ='bloco 01'!C27 | C38: ='bloco 01'!D27 | D38: ='bloco 01'!E27 | E38: =IFERROR(('bloco 01'!F27),"") | F38: ='bloco 01'!G27
A39: ='bloco 01'!$B$28 | B39: ='bloco 01'!C28 | C39: ='bloco 01'!D28 | D39: ='bloco 01'!E28 | E39: =IFERROR(('bloco 01'!F28),"") | F39: ='bloco 01'!G28
A40: ='bloco 01'!$B$29 | B40: ='bloco 01'!C29 | C40: ='bloco 01'!D29 | D40: ='bloco 01'!E29 | E40: =IFERROR(('bloco 01'!F29),"") | F40: ='bloco 01'!G29
A41: ='bloco 01'!$B$30 | B41: ='bloco 01'!C30 | C41: ='bloco 01'!D30 | D41: ='bloco 01'!E30 | E41: =IFERROR(('bloco 01'!F30),"") | F41: ='bloco 01'!G30
A42: TREINO 03
B43: SETS | C43: REPS | D43: KG | E43: %1RM / PSE | F43: OBS
A44: ='bloco 01'!$B$36 | B44: ='bloco 01'!C36 | C44: ='bloco 01'!D36 | D44: ='bloco 01'!E36 | E44: =IFERROR(('bloco 01'!F36),"") | F44: ='bloco 01'!G36
A45: ='bloco 01'!$B$37 | B45: ='bloco 01'!C37 | C45: ='bloco 01'!D37 | D45: ='bloco 01'!E37 | E45: =IFERROR(('bloco 01'!F37),"") | F45: ='bloco 01'!G37
A46: ='bloco 01'!$B$38 | B46: ='bloco 01'!C38 | C46: ='bloco 01'!D38 | D46: ='bloco 01'!E38 | E46: =IFERROR(('bloco 01'!F38),"") | F46: ='bloco 01'!G38
A47: ='bloco 01'!$B$39 | B47: ='bloco 01'!C39 | C47: ='bloco 01'!D39 | D47: ='bloco 01'!E39 | E47: =IFERROR(('bloco 01'!F39),"") | F47: ='bloco 01'!G39
A48: ='bloco 01'!$B$40 | B48: ='bloco 01'!C40 | C48: ='bloco 01'!D40 | D48: ='bloco 01'!E40 | E48: =IFERROR(('bloco 01'!F40),"") | F48: ='bloco 01'!G40
...

Sheet bloco 01
A1: BLOCO 01
A3: TREINO 01 | C3: =macro!B6 | J3: =C3+7 | Q3: =J3+7 | X3: =Q3+7
C4: SETS | D4: REPS | E4: KG | F4: %1RM | G4: OBS | J4: SETS | K4: REPS | L4: KG | M4: %1RM | N4: OBS | Q4: SETS | R4: REPS | S4: KG | T4: %1RM | U4: OBS | X4: SETS | Y4: REPS | Z4: KG | AA4: %1RM | AB4: OBS
B5: exercícios | F5: pse | I5: exercícios | M5: pse | P5: exercícios | T5: pse | W5: exercícios | AA5: pse
F6: =IFERROR(__xludf.DUMMYFUNCTION("IFERROR($E6/INDEX(prs!$D$6:$D$12,MATCH(TRUE,ARRAYFORMULA(ISNUMBER(SEARCH(prs!$A$6:$A$12,$B6))),0)),"""")"),"") | M6: =IFERROR(__xludf.DUMMYFUNCTION("IFERROR($L6/INDEX(prs!$D$6:$D$12,MATCH(TRUE,ARRAYFORMULA(ISNUMBER(SEARCH(prs!$A$6:$A$12,$I6))),0)),"""")"),"") | T6: =IFERROR(__xludf.DUMMYFUNCTION("IFERROR($S6/INDEX(prs!$D$6:$D$12,MATCH(TRUE,ARRAYFORMULA(ISNUMBER(SEARCH(prs!$A$6:$A$12,$P6))),0)),"""")"),"") | AA6: =IFERROR(__xludf.DUMMYFUNCTION("IFERROR($Z6/INDEX(prs!$D$6:$D$12,MATCH(TRUE,ARRAYFORMULA(ISNUMBER(SEARCH(prs!$A$6:$A$12,$W6))),0)),"""")"),"")
F7: =IFERROR(__xludf.DUMMYFUNCTION("IFERROR($E7/INDEX(prs!$D$6:$D$12,MATCH(TRUE,ARRAYFORMULA(ISNUMBER(SEARCH(prs!$A$6:$A$12,$B7))),0)),"""")"),"") | M7: =IFERROR(__xludf.DUMMYFUNCTION("IFERROR($L7/INDEX(prs!$D$6:$D$12,MATCH(TRUE,ARRAYFORMULA(ISNUMBER(SEARCH(prs!$A$6:$A$12,$I7))),0)),"""")"),"") | T7: =IFERROR(__xludf.DUMMYFUNCTION("IFERROR($S7/INDEX(prs!$D$6:$D$12,MATCH(TRUE,ARRAYFORMULA(ISNUMBER(SEARCH(prs!$A$6:$A$12,$P7))),0)),"""")"),"") | AA7: =IFERROR(__xludf.DUMMYFUNCTION("IFERROR($Z7/INDEX(prs!$D$6:$D$12,MATCH(TRUE,ARRAYFORMULA(ISNUMBER(SEARCH(prs!$A$6:$A$12,$W7))),0)),"""")"),"")
F8: =IFERROR(__xludf.DUMMYFUNCTION("IFERROR($E8/INDEX(prs!$D$6:$D$12,MATCH(TRUE,ARRAYFORMULA(ISNUMBER(SEARCH(prs!$A$6:$A$12,$B8))),0)),"""")"),"") | M8: =IFERROR(__xludf.DUMMYFUNCTION("IFERROR($L8/INDEX(prs!$D$6:$D$12,MATCH(TRUE,ARRAYFORMULA(ISNUMBER(SEARCH(prs!$A$6:$A$12,$I8))),0)),"""")"),"") | T8: =IFERROR(__xludf.DUMMYFUNCTION("IFERROR($S8/INDEX(prs!$D$6:$D$12,MATCH(TRUE,ARRAYFORMULA(ISNUMBER(SEARCH(prs!$A$6:$A$12,$P8))),0)),"""")"),"") | AA8: =IFERROR(__xludf.DUMMYFUNCTION("IFERROR($Z8/INDEX(prs!$D$6:$D$12,MATCH(TRUE,ARRAYFORMULA(ISNUMBER(SEARCH(prs!$A$6:$A$12,$W8))),0)),"""")"),"")
F9: =IFERROR(__xludf.DUMMYFUNCTION("IFERROR($E9/INDEX(prs!$D$6:$D$12,MATCH(TRUE,ARRAYFORMULA(ISNUMBER(SEARCH(prs!$A$6:$A$12,$B9))),0)),"""")"),"") | M9: =IFERROR(__xludf.DUMMYFUNCTION("IFERROR($L9/INDEX(prs!$D$6:$D$12,MATCH(TRUE,ARRAYFORMULA(ISNUMBER(SEARCH(prs!$A$6:$A$12,$I9))),0)),"""")"),"") | T9: =IFERROR(__xludf.DUMMYFUNCTION("IFERROR($S9/INDEX(prs!$D$6:$D$12,MATCH(TRUE,ARRAYFORMULA(ISNUMBER(SEARCH(prs!$A$6:$A$12,$P9))),0)),"""")"),"") | AA9: =IFERROR(__xludf.DUMMYFUNCTION("IFERROR($Z9/INDEX(prs!$D$6:$D$12,MATCH(TRUE,ARRAYFORMULA(ISNUMBER(SEARCH(prs!$A$6:$A$12,$W9))),0)),"""")"),"")
F10: =IFERROR(__xludf.DUMMYFUNCTION("IFERROR($E10/INDEX(prs!$D$6:$D$12,MATCH(TRUE,ARRAYFORMULA(ISNUMBER(SEARCH(prs!$A$6:$A$12,$B10))),0)),"""")"),"") | M10: =IFERROR(__xludf.DUMMYFUNCTION("IFERROR($L10/INDEX(prs!$D$6:$D$12,MATCH(TRUE,ARRAYFORMULA(ISNUMBER(SEARCH(prs!$A$6:$A$12,$I10))),0)),"""")"),"") | T10: =IFERROR(__xludf.DUMMYFUNCTION("IFERROR($S10/INDEX(prs!$D$6:$D$12,MATCH(TRUE,ARRAYFORMULA(ISNUMBER(SEARCH(prs!$A$6:$A$12,$P10))),0)),"""")"),"") | AA10: =IFERROR(__xludf.DUMMYFUNCTION("IFERROR($Z10/INDEX(prs!$D$6:$D$12,MATCH(TRUE,ARRAYFORMULA(ISNUMBER(SEARCH(prs!$A$6:$A$12,$W10))),0)),"""")"),"")
F11: =IFERROR(__xludf.DUMMYFUNCTION("IFERROR($E11/INDEX(prs!$D$6:$D$12,MATCH(TRUE,ARRAYFORMULA(ISNUMBER(SEARCH(prs!$A$6:$A$12,$B11))),0)),"""")"),"") | M11: =IFERROR(__xludf.DUMMYFUNCTION("IFERROR($L11/INDEX(prs!$D$6:$D$12,MATCH(TRUE,ARRAYFORMULA(ISNUMBER(SEARCH(prs!$A$6:$A$12,$I11))),0)),"""")"),"") | T11: =IFERROR(__xludf.DUMMYFUNCTION("IFERROR($S11/INDEX(prs!$D$6:$D$12,MATCH(TRUE,ARRAYFORMULA(ISNUMBER(SEARCH(prs!$A$6:$A$12,$P11))),0)),"""")"),"") | AA11: =IFERROR(__xludf.DUMMYFUNCTION("IFERROR($Z11/INDEX(prs!$D$6:$D$12,MATCH(TRUE,ARRAYFORMULA(ISNUMBER(SEARCH(prs!$A$6:$A$12,$W11))),0)),"""")"),"")
F12: =IFERROR(__xludf.DUMMYFUNCTION("IFERROR($E12/INDEX(prs!$D$6:$D$12,MATCH(TRUE,ARRAYFORMULA(ISNUMBER(SEARCH(prs!$A$6:$A$12,$B12))),0)),"""")"),"") | M12: =IFERROR(__xludf.DUMMYFUNCTION("IFERROR($L12/INDEX(prs!$D$6:$D$12,MATCH(TRUE,ARRAYFORMULA(ISNUMBER(SEARCH(prs!$A$6:$A$12,$I12))),0)),"""")"),"") | T12: =IFERROR(__xludf.DUMMYFUNCTION("IFERROR($S12/INDEX(prs!$D$6:$D$12,MATCH(TRUE,ARRAYFORMULA(ISNUMBER(SEARCH(prs!$A$6:$A$12,$P12))),0)),"""")"),"") | AA12: =IFERROR(__xludf.DUMMYFUNCTION("IFERROR($Z12/INDEX(prs!$D$6:$D$12,MATCH(TRUE,ARRAYFORMULA(ISNUMBER(SEARCH(prs!$A$6:$A$12,$W12))),0)),"""")"),"")
F13: =IFERROR(__xludf.DUMMYFUNCTION("IFERROR($E13/INDEX(prs!$D$6:$D$12,MATCH(TRUE,ARRAYFORMULA(ISNUMBER(SEARCH(prs!$A$6:$A$12,$B13))),0)),"""")"),"") | M13: =IFERROR(__xludf.DUMMYFUNCTION("IFERROR($L13/INDEX(prs!$D$6:$D$12,MATCH(TRUE,ARRAYFORMULA(ISNUMBER(SEARCH(prs!$A$6:$A$12,$I13))),0)),"""")"),"") | T13: =IFERROR(__xludf.DUMMYFUNCTION("IFERROR($S13/INDEX(prs!$D$6:$D$12,MATCH(TRUE,ARRAYFORMULA(ISNUMBER(SEARCH(prs!$A$6:$A$12,$P13))),0)),"""")"),"") | AA13: =IFERROR(__xludf.DUMMYFUNCTION("IFERROR($Z13/INDEX(prs!$D$6:$D$12,MATCH(TRUE,ARRAYFORMULA(ISNUMBER(SEARCH(prs!$A$6:$A$12,$W13))),0)),"""")"),"")
F14: =IFERROR(__xludf.DUMMYFUNCTION("IFERROR($E14/INDEX(prs!$D$6:$D$12,MATCH(TRUE,ARRAYFORMULA(ISNUMBER(SEARCH(prs!$A$6:$A$12,$B14))),0)),"""")"),"") | M14: =IFERROR(__xludf.DUMMYFUNCTION("IFERROR($L14/INDEX(prs!$D$6:$D$12,MATCH(TRUE,ARRAYFORMULA(ISNUMBER(SEARCH(prs!$A$6:$A$12,$I14))),0)),"""")"),"") | T14: =IFERROR(__xludf.DUMMYFUNCTION("IFERROR($S14/INDEX(prs!$D$6:$D$12,MATCH(TRUE,ARRAYFORMULA(ISNUMBER(SEARCH(prs!$A$6:$A$12,$P14))),0)),"""")"),"") | AA14: =IFERROR(__xludf.DUMMYFUNCTION("IFERROR($Z14/INDEX(prs!$D$6:$D$12,MATCH(TRUE,ARRAYFORMULA(ISNUMBER(SEARCH(prs!$A$6:$A$12,$W14))),0)),"""")"),"")
F15: =IFERROR(__xludf.DUMMYFUNCTION("IFERROR($E15/INDEX(prs!$D$6:$D$12,MATCH(TRUE,ARRAYFORMULA(ISNUMBER(SEARCH(prs!$A$6:$A$12,$B15))),0)),"""")"),"") | M15: =IFERROR(__xludf.DUMMYFUNCTION("IFERROR($L15/INDEX(prs!$D$6:$D$12,MATCH(TRUE,ARRAYFORMULA(ISNUMBER(SEARCH(prs!$A$6:$A$12,$I15))),0)),"""")"),"") | T15: =IFERROR(__xludf.DUMMYFUNCTION("IFERROR($S15/INDEX(prs!$D$6:$D$12,MATCH(TRUE,ARRAYFORMULA(ISNUMBER(SEARCH(prs!$A$6:$A$12,$P15))),0)),"""")"),"") | AA15: =IFERROR(__xludf.DUMMYFUNCTION("IFERROR($Z15/INDEX(prs!$D$6:$D$12,MATCH(TRUE,ARRAYFORMULA(ISNUMBER(SEARCH(prs!$A$6:$A$12,$W15))),0)),"""")"),"")
C16: SEMANA 01 | J16: SEMANA 02 | Q16: SEMANA 03 | X16: SEMANA 04
A18: TREINO 02
C19: SETS | D19: REPS | E19: KG | F19: %1RM | G19: OBS | J19: SETS | K19: REPS | L19: KG | M19: %1RM | N19: OBS | Q19: SETS | R19: REPS | S19: KG | T19: %1RM | U19: OBS | X19: SETS | Y19: REPS | Z19: KG | AA19: %1RM | AB19: OBS
B20: exercícios | F20: pse | I20: exercícios | M20: pse | P20: exercícios | T20: pse | W20: exercícios | AA20: pse
F21: =IFERROR(__xludf.DUMMYFUNCTION("IFERROR($E21/INDEX(prs!$D$6:$D$12,MATCH(TRUE,ARRAYFORMULA(ISNUMBER(SEARCH(prs!$A$6:$A$12,$B21))),0)),"""")"),"") | M21: =IFERROR(__xludf.DUMMYFUNCTION("IFERROR($L21/INDEX(prs!$D$6:$D$12,MATCH(TRUE,ARRAYFORMULA(ISNUMBER(SEARCH(prs!$A$6:$A$12,$I21))),0)),"""")"),"") | T21: =IFERROR(__xludf.DUMMYFUNCTION("IFERROR($S21/INDEX(prs!$D$6:$D$12,MATCH(TRUE,ARRAYFORMULA(ISNUMBER(SEARCH(prs!$A$6:$A$12,$P21))),0)),"""")"),"") | AA21: =IFERROR(__xludf.DUMMYFUNCTION("IFERROR($Z21/INDEX(prs!$D$6:$D$12,MATCH(TRUE,ARRAYFORMULA(ISNUMBER(SEARCH(prs!$A$6:$A$12,$W21))),0)),"""")"),"")
F22: =IFERROR(__xludf.DUMMYFUNCTION("IFERROR($E22/INDEX(prs!$D$6:$D$12,MATCH(TRUE,ARRAYFORMULA(ISNUMBER(SEARCH(prs!$A$6:$A$12,$B22))),0)),"""")"),"") | M22: =IFERROR(__xludf.DUMMYFUNCTION("IFERROR($L22/INDEX(prs!$D$6:$D$12,MATCH(TRUE,ARRAYFORMULA(ISNUMBER(SEARCH(prs!$A$6:$A$12,$I22))),0)),"""")"),"") | T22: =IFERROR(__xludf.DUMMYFUNCTION("IFERROR($S22/INDEX(prs!$D$6:$D$12,MATCH(TRUE,ARRAYFORMULA(ISNUMBER(SEARCH(prs!$A$6:$A$12,$P22))),0)),"""")"),"") | AA22: =IFERROR(__xludf.DUMMYFUNCTION("IFERROR($Z22/INDEX(prs!$D$6:$D$12,MATCH(TRUE,ARRAYFORMULA(ISNUMBER(SEARCH(prs!$A$6:$A$12,$W22))),0)),"""")"),"")
F23: =IFERROR(__xludf.DUMMYFUNCTION("IFERROR($E23/INDEX(prs!$D$6:$D$12,MATCH(TRUE,ARRAYFORMULA(ISNUMBER(SEARCH(prs!$A$6:$A$12,$B23))),0)),"""")"),"") | M23: =IFERROR(__xludf.DUMMYFUNCTION("IFERROR($L23/INDEX(prs!$D$6:$D$12,MATCH(TRUE,ARRAYFORMULA(ISNUMBER(SEARCH(prs!$A$6:$A$12,$I23))),0)),"""")"),"") | T23: =IFERROR(__xludf.DUMMYFUNCTION("IFERROR($S23/INDEX(prs!$D$6:$D$12,MATCH(TRUE,ARRAYFORMULA(ISNUMBER(SEARCH(prs!$A$6:$A$12,$P23))),0)),"""")"),"") | AA23: =IFERROR(__xludf.DUMMYFUNCTION("IFERROR($Z23/INDEX(prs!$D$6:$D$12,MATCH(TRUE,ARRAYFORMULA(ISNUMBER(SEARCH(prs!$A$6:$A$12,$W23))),0)),"""")"),"")
F24: =IFERROR(__xludf.DUMMYFUNCTION("IFERROR($E24/INDEX(prs!$D$6:$D$12,MATCH(TRUE,ARRAYFORMULA(ISNUMBER(SEARCH(prs!$A$6:$A$12,$B24))),0)),"""")"),"") | M24: =IFERROR(__xludf.DUMMYFUNCTION("IFERROR($L24/INDEX(prs!$D$6:$D$12,MATCH(TRUE,ARRAYFORMULA(ISNUMBER(SEARCH(prs!$A$6:$A$12,$I24))),0)),"""")"),"") | T24: =IFERROR(__xludf.DUMMYFUNCTION("IFERROR($S24/INDEX(prs!$D$6:$D$12,MATCH(TRUE,ARRAYFORMULA(ISNUMBER(SEARCH(prs!$A$6:$A$12,$P24))),0)),"""")"),"") | AA24: =IFERROR(__xludf.DUMMYFUNCTION("IFERROR($Z24/INDEX(prs!$D$6:$D$12,MATCH(TRUE,ARRAYFORMULA(ISNUMBER(SEARCH(prs!$A$6:$A$12,$W24))),0)),"""")"),"")
F25: =IFERROR(__xludf.DUMMYFUNCTION("IFERROR($E25/INDEX(prs!$D$6:$D$12,MATCH(TRUE,ARRAYFORMULA(ISNUMBER(SEARCH(prs!$A$6:$A$12,$B25))),0)),"""")"),"") | M25: =IFERROR(__xludf.DUMMYFUNCTION("IFERROR($L25/INDEX(prs!$D$6:$D$12,MATCH(TRUE,ARRAYFORMULA(ISNUMBER(SEARCH(prs!$A$6:$A$12,$I25))),0)),"""")"),"") | T25: =IFERROR(__xludf.DUMMYFUNCTION("IFERROR($S25/INDEX(prs!$D$6:$D$12,MATCH(TRUE,ARRAYFORMULA(ISNUMBER(SEARCH(prs!$A$6:$A$12,$P25))),0)),"""")"),"") | AA25: =IFERROR(__xludf.DUMMYFUNCTION("IFERROR($Z25/INDEX(prs!$D$6:$D$12,MATCH(TRUE,ARRAYFORMULA(ISNUMBER(SEARCH(prs!$A$6:$A$12,$W25))),0)),"""")"),"")
F26: =IFERROR(__xludf.DUMMYFUNCTION("IFERROR($E26/INDEX(prs!$D$6:$D$12,MATCH(TRUE,ARRAYFORMULA(ISNUMBER(SEARCH(prs!$A$6:$A$12,$B26))),0)),"""")"),"") | M26: =IFERROR(__xludf.DUMMYFUNCTION("IFERROR($L26/INDEX(prs!$D$6:$D$12,MATCH(TRUE,ARRAYFORMULA(ISNUMBER(SEARCH(prs!$A$6:$A$12,$I26))),0)),"""")"),"") | T26: =IFERROR(__xludf.DUMMYFUNCTION("IFERROR($S26/INDEX(prs!$D$6:$D$12,MATCH(TRUE,ARRAYFORMULA(ISNUMBER(SEARCH(prs!$A$6:$A$12,$P26))),0)),"""")"),"") | AA26: =IFERROR(__xludf.DUMMYFUNCTION("IFERROR($Z26/INDEX(prs!$D$6:$D$12,MATCH(TRUE,ARRAYFORMULA(ISNUMBER(SEARCH(prs!$A$6:$A$12,$W26))),0)),"""")"),"")
F27: =IFERROR(__xludf.DUMMYFUNCTION("IFERROR($E27/INDEX(prs!$D$6:$D$12,MATCH(TRUE,ARRAYFORMULA(ISNUMBER(SEARCH(prs!$A$6:$A$12,$B27))),0)),"""")"),"") | M27: =IFERROR(__xludf.DUMMYFUNCTION("IFERROR($L27/INDEX(prs!$D$6:$D$12,MATCH(TRUE,ARRAYFORMULA(ISNUMBER(SEARCH(prs!$A$6:$A$12,$I27))),0)),"""")"),"") | T27: =IFERROR(__xludf.DUMMYFUNCTION("IFERROR($S27/INDEX(prs!$D$6:$D$12,MATCH(TRUE,ARRAYFORMULA(ISNUMBER(SEARCH(prs!$A$6:$A$12,$P27))),0)),"""")"),"") | AA27: =IFERROR(__xludf.DUMMYFUNCTION("IFERROR($Z27/INDEX(prs!$D$6:$D$12,MATCH(TRUE,ARRAYFORMULA(ISNUMBER(SEARCH(prs!$A$6:$A$12,$W27))),0)),"""")"),"")
F28: =IFERROR(__xludf.DUMMYFUNCTION("IFERROR($E28/INDEX(prs!$D$6:$D$12,MATCH(TRUE,ARRAYFORMULA(ISNUMBER(SEARCH(prs!$A$6:$A$12,$B28))),0)),"""")"),"") | M28: =IFERROR(__xludf.DUMMYFUNCTION("IFERROR($L28/INDEX(prs!$D$6:$D$12,MATCH(TRUE,ARRAYFORMULA(ISNUMBER(SEARCH(prs!$A$6:$A$12,$I28))),0)),"""")"),"") | T28: =IFERROR(__xludf.DUMMYFUNCTION("IFERROR($S28/INDEX(prs!$D$6:$D$12,MATCH(TRUE,ARRAYFORMULA(ISNUMBER(SEARCH(prs!$A$6:$A$12,$P28))),0)),"""")"),"") | AA28: =IFERROR(__xludf.DUMMYFUNCTION("IFERROR($Z28/INDEX(prs!$D$6:$D$12,MATCH(TRUE,ARRAYFORMULA(ISNUMBER(SEARCH(prs!$A$6:$A$12,$W28))),0)),"""")"),"")
F29: =IFERROR(__xludf.DUMMYFUNCTION("IFERROR($E29/INDEX(prs!$D$6:$D$12,MATCH(TRUE,ARRAYFORMULA(ISNUMBER(SEARCH(prs!$A$6:$A$12,$B29))),0)),"""")"),"") | M29: =IFERROR(__xludf.DUMMYFUNCTION("IFERROR($L29/INDEX(prs!$D$6:$D$12,MATCH(TRUE,ARRAYFORMULA(ISNUMBER(SEARCH(prs!$A$6:$A$12,$I29))),0)),"""")"),"") | T29: =IFERROR(__xludf.DUMMYFUNCTION("IFERROR($S29/INDEX(prs!$D$6:$D$12,MATCH(TRUE,ARRAYFORMULA(ISNUMBER(SEARCH(prs!$A$6:$A$12,$P29))),0)),"""")"),"") | AA29: =IFERROR(__xludf.DUMMYFUNCTION("IFERROR($Z29/INDEX(prs!$D$6:$D$12,MATCH(TRUE,ARRAYFORMULA(ISNUMBER(SEARCH(prs!$A$6:$A$12,$W29))),0)),"""")"),"")
F30: =IFERROR(__xludf.DUMMYFUNCTION("IFERROR($E30/INDEX(prs!$D$6:$D$12,MATCH(TRUE,ARRAYFORMULA(ISNUMBER(SEARCH(prs!$A$6:$A$12,$B30))),0)),"""")"),"") | M30: =IFERROR(__xludf.DUMMYFUNCTION("IFERROR($L30/INDEX(prs!$D$6:$D$12,MATCH(TRUE,ARRAYFORMULA(ISNUMBER(SEARCH(prs!$A$6:$A$12,$I30))),0)),"""")"),"") | T30: =IFERROR(__xludf.DUMMYFUNCTION("IFERROR($S30/INDEX(prs!$D$6:$D$12,MATCH(TRUE,ARRAYFORMULA(ISNUMBER(SEARCH(prs!$A$6:$A$12,$P30))),0)),"""")"),"") | AA30: =IFERROR(__xludf.DUMMYFUNCTION("IFERROR($Z30/INDEX(prs!$D$6:$D$12,MATCH(TRUE,ARRAYFORMULA(ISNUMBER(SEARCH(prs!$A$6:$A$12,$W30))),0)),"""")"),"")
C31: SEMANA 01 | J31: SEMANA 02 | Q31: SEMANA 03 | X31: SEMANA 04
A33: TREINO 03
C34: SETS | D34: REPS | E34: KG | F34: %1RM | G34: OBS | J34: SETS | K34: REPS | L34: KG | M34: %1RM | N34: OBS | Q34: SETS | R34: REPS | S34: KG | T34: %1RM | U34: OBS | X34: SETS | Y34: REPS | Z34: KG | AA34: %1RM | AB34: OBS
B35: exercícios | F35: pse | I35: exercícios | M35: pse | P35: exercícios | T35: pse | W35: exercícios | AA35: pse
F36: =IFERROR(__xludf.DUMMYFUNCTION("IFERROR($E36/INDEX(prs!$D$6:$D$12,MATCH(TRUE,ARRAYFORMULA(ISNUMBER(SEARCH(prs!$A$6:$A$12,$B36))),0)),"""")"),"") | M36: =IFERROR(__xludf.DUMMYFUNCTION("IFERROR($L36/INDEX(prs!$D$6:$D$12,MATCH(TRUE,ARRAYFORMULA(ISNUMBER(SEARCH(prs!$A$6:$A$12,$I36))),0)),"""")"),"") | T36: =IFERROR(__xludf.DUMMYFUNCTION("IFERROR($S36/INDEX(prs!$D$6:$D$12,MATCH(TRUE,ARRAYFORMULA(ISNUMBER(SEARCH(prs!$A$6:$A$12,$P36))),0)),"""")"),"") | AA36: =IFERROR(__xludf.DUMMYFUNCTION("IFERROR($Z36/INDEX(prs!$D$6:$D$12,MATCH(TRUE,ARRAYFORMULA(ISNUMBER(SEARCH(prs!$A$6:$A$12,$W36))),0)),"""")"),"")
F37: =IFERROR(__xludf.DUMMYFUNCTION("IFERROR($E37/INDEX(prs!$D$6:$D$12,MATCH(TRUE,ARRAYFORMULA(ISNUMBER(SEARCH(prs!$A$6:$A$12,$B37))),0)),"""")"),"") | M37: =IFERROR(__xludf.DUMMYFUNCTION("IFERROR($L37/INDEX(prs!$D$6:$D$12,MATCH(TRUE,ARRAYFORMULA(ISNUMBER(SEARCH(prs!$A$6:$A$12,$I37))),0)),"""")"),"") | T37: =IFERROR(__xludf.DUMMYFUNCTION("IFERROR($S37/INDEX(prs!$D$6:$D$12,MATCH(TRUE,ARRAYFORMULA(ISNUMBER(SEARCH(prs!$A$6:$A$12,$P37))),0)),"""")"),"") | AA37: =IFERROR(__xludf.DUMMYFUNCTION("IFERROR($Z37/INDEX(prs!$D$6:$D$12,MATCH(TRUE,ARRAYFORMULA(ISNUMBER(SEARCH(prs!$A$6:$A$12,$W37))),0)),"""")"),"")
F38: =IFERROR(__xludf.DUMMYFUNCTION("IFERROR($E38/INDEX(prs!$D$6:$D$12,MATCH(TRUE,ARRAYFORMULA(ISNUMBER(SEARCH(prs!$A$6:$A$12,$B38))),0)),"""")"),"") | M38: =IFERROR(__xludf.DUMMYFUNCTION("IFERROR($L38/INDEX(prs!$D$6:$D$12,MATCH(TRUE,ARRAYFORMULA(ISNUMBER(SEARCH(prs!$A$6:$A$12,$I38))),0)),"""")"),"") | T38: =IFERROR(__xludf.DUMMYFUNCTION("IFERROR($S38/INDEX(prs!$D$6:$D$12,MATCH(TRUE,ARRAYFORMULA(ISNUMBER(SEARCH(prs!$A$6:$A$12,$P38))),0)),"""")"),"") | AA38: =IFERROR(__xludf.DUMMYFUNCTION("IFERROR($Z38/INDEX(prs!$D$6:$D$12,MATCH(TRUE,ARRAYFORMULA(ISNUMBER(SEARCH(prs!$A$6:$A$12,$W38))),0)),"""")"),"")
F39: =IFERROR(__xludf.DUMMYFUNCTION("IFERROR($E39/INDEX(prs!$D$6:$D$12,MATCH(TRUE,ARRAYFORMULA(ISNUMBER(SEARCH(prs!$A$6:$A$12,$B39))),0)),"""")"),"") | M39: =IFERROR(__xludf.DUMMYFUNCTION("IFERROR($L39/INDEX(prs!$D$6:$D$12,MATCH(TRUE,ARRAYFORMULA(ISNUMBER(SEARCH(prs!$A$6:$A$12,$I39))),0)),"""")"),"") | T39: =IFERROR(__xludf.DUMMYFUNCTION("IFERROR($S39/INDEX(prs!$D$6:$D$12,MATCH(TRUE,ARRAYFORMULA(ISNUMBER(SEARCH(prs!$A$6:$A$12,$P39))),0)),"""")"),"") | AA39: =IFERROR(__xludf.DUMMYFUNCTION("IFERROR($Z39/INDEX(prs!$D$6:$D$12,MATCH(TRUE,ARRAYFORMULA(ISNUMBER(SEARCH(prs!$A$6:$A$12,$W39))),0)),"""")"),"")
F40: =IFERROR(__xludf.DUMMYFUNCTION("IFERROR($E40/INDEX(prs!$D$6:$D$12,MATCH(TRUE,ARRAYFORMULA(ISNUMBER(SEARCH(prs!$A$6:$A$12,$B40))),0)),"""")"),"") | M40: =IFERROR(__xludf.DUMMYFUNCTION("IFERROR($L40/INDEX(prs!$D$6:$D$12,MATCH(TRUE,ARRAYFORMULA(ISNUMBER(SEARCH(prs!$A$6:$A$12,$I40))),0)),"""")"),"") | T40: =IFERROR(__xludf.DUMMYFUNCTION("IFERROR($S40/INDEX(prs!$D$6:$D$12,MATCH(TRUE,ARRAYFORMULA(ISNUMBER(SEARCH(prs!$A$6:$A$12,$P40))),0)),"""")"),"") | AA40: =IFERROR(__xludf.DUMMYFUNCTION("IFERROR($Z40/INDEX(prs!$D$6:$D$12,MATCH(TRUE,ARRAYFORMULA(ISNUMBER(SEARCH(prs!$A$6:$A$12,$W40))),0)),"""")"),"")
F41: =IFERROR(__xludf.DUMMYFUNCTION("IFERROR($E41/INDEX(prs!$D$6:$D$12,MATCH(TRUE,ARRAYFORMULA(ISNUMBER(SEARCH(prs!$A$6:$A$12,$B41))),0)),"""")"),"") | M41: =IFERROR(__xludf.DUMMYFUNCTION("IFERROR($L41/INDEX(prs!$D$6:$D$12,MATCH(TRUE,ARRAYFORMULA(ISNUMBER(SEARCH(prs!$A$6:$A$12,$I41))),0)),"""")"),"") | T41: =IFERROR(__xludf.DUMMYFUNCTION("IFERROR($S41/INDEX(prs!$D$6:$D$12,MATCH(TRUE,ARRAYFORMULA(ISNUMBER(SEARCH(prs!$A$6:$A$12,$P41))),0)),"""")"),"") | AA41: =IFERROR(__xludf.DUMMYFUNCTION("IFERROR($Z41/INDEX(prs!$D$6:$D$12,MATCH(TRUE,ARRAYFORMULA(ISNUMBER(SEARCH(prs!$A$6:$A$12,$W41))),0)),"""")"),"")
F42: =IFERROR(__xludf.DUMMYFUNCTION("IFERROR($E42/INDEX(prs!$D$6:$D$12,MATCH(TRUE,ARRAYFORMULA(ISNUMBER(SEARCH(prs!$A$6:$A$12,$B42))),0)),"""")"),"") | M42: =IFERROR(__xludf.DUMMYFUNCTION("IFERROR($L42/INDEX(prs!$D$6:$D$12,MATCH(TRUE,ARRAYFORMULA(ISNUMBER(SEARCH(prs!$A$6:$A$12,$I42))),0)),"""")"),"") | T42: =IFERROR(__xludf.DUMMYFUNCTION("IFERROR($S42/INDEX(prs!$D$6:$D$12,MATCH(TRUE,ARRAYFORMULA(ISNUMBER(SEARCH(prs!$A$6:$A$12,$P42))),0)),"""")"),"") | AA42: =IFERROR(__xludf.DUMMYFUNCTION("IFERROR($Z42/INDEX(prs!$D$6:$D$12,MATCH(TRUE,ARRAYFORMULA(ISNUMBER(SEARCH(prs!$A$6:$A$12,$W42))),0)),"""")"),"")
F43: =IFERROR(__xludf.DUMMYFUNCTION("IFERROR($E43/INDEX(prs!$D$6:$D$12,MATCH(TRUE,ARRAYFORMULA(ISNUMBER(SEARCH(prs!$A$6:$A$12,$B43))),0)),"""")"),"") | M43: =IFERROR(__xludf.DUMMYFUNCTION("IFERROR($L43/INDEX(prs!$D$6:$D$12,MATCH(TRUE,ARRAYFORMULA(ISNUMBER(SEARCH(prs!$A$6:$A$12,$I43))),0)),"""")"),"") | T43: =IFERROR(__xludf.DUMMYFUNCTION("IFERROR($S43/INDEX(prs!$D$6:$D$12,MATCH(TRUE,ARRAYFORMULA(ISNUMBER(SEARCH(prs!$A$6:$A$12,$P43))),0)),"""")"),"") | AA43: =IFERROR(__xludf.DUMMYFUNCTION("IFERROR($Z43/INDEX(prs!$D$6:$D$12,MATCH(TRUE,ARRAYFORMULA(ISNUMBER(SEARCH(prs!$A$6:$A$12,$W43))),0)),"""")"),"")
...

Sheet aluno 02
B1: PLANILHA DE TREINAMENTO
B2: NOME | C2: ='aluno 01'!C2
B3: OBJETIVO | C3: ='aluno 01'!C3
B5: SEGUNDA | C5: TERÇA | D5: QUARTA | E5: QUINTA | F5: SEXTA
B6: ='aluno 01'!B6 | C6: ='aluno 01'!C6 | D6: ='aluno 01'!D6 | E6: ='aluno 01'!E6 | F6: ='aluno 01'!F6
A8: OBS
A9: ='aluno 01'!A9
A11: AQC
B12: SETS | C12: REPS / TEMPO | D12: KG | E12: OBS
A16: ='bloco 02'!C3
A17: SEMANA 01
A18: TREINO 01
B19: SETS | C19: REPS | D19: KG | E19: %1RM / PSE | F19: OBS
A20: ='bloco 02'!$B6 | B20: ='bloco 02'!C6 | C20: ='bloco 02'!D6 | D20: ='bloco 02'!E6 | E20: =IFERROR(('bloco 02'!F6),"") | F20: ='bloco 02'!G6
A21: ='bloco 02'!$B7 | B21: ='bloco 02'!C7 | C21: ='bloco 02'!D7 | D21: ='bloco 02'!E7 | E21: =IFERROR(('bloco 02'!F7),"") | F21: ='bloco 02'!G7
A22: ='bloco 02'!$B8 | B22: ='bloco 02'!C8 | C22: ='bloco 02'!D8 | D22: ='bloco 02'!E8 | E22: =IFERROR(('bloco 02'!F8),"") | F22: ='bloco 02'!G8
A23: ='bloco 02'!$B9 | B23: ='bloco 02'!C9 | C23: ='bloco 02'!D9 | D23: ='bloco 02'!E9 | E23: =IFERROR(('bloco 02'!F9),"") | F23: ='bloco 02'!G9
A24: ='bloco 02'!$B10 | B24: ='bloco 02'!C10 | C24: ='bloco 02'!D10 | D24: ='bloco 02'!E10 | E24: =IFERROR(('bloco 02'!F10),"") | F24: ='bloco 02'!G10
A25: ='bloco 02'!$B11 | B25: ='bloco 02'!C11 | C25: ='bloco 02'!D11 | D25: ='bloco 02'!E11 | E25: =IFERROR(('bloco 02'!F11),"") | F25: ='bloco 02'!G11
A26: ='bloco 02'!$B12 | B26: ='bloco 02'!C12 | C26: ='bloco 02'!D12 | D26: ='bloco 02'!E12 | E26: =IFERROR(('bloco 02'!F12),"") | F26: ='bloco 02'!G12
A27: ='bloco 02'!$B13 | B27: ='bloco 02'!C13 | C27: ='bloco 02'!D13 | D27: ='bloco 02'!E13 | E27: =IFERROR(('bloco 02'!F13),"") | F27: ='bloco 02'!G13
A28: ='bloco 02'!$B14 | B28: ='bloco 02'!C14 | C28: ='bloco 02'!D14 | D28: ='bloco 02'!E14 | E28: =IFERROR(('bloco 02'!F14),"") | F28: ='bloco 02'!G14
A29: ='bloco 02'!$B15 | B29: ='bloco 02'!C15 | C29: ='bloco 02'!D15 | D29: ='bloco 02'!E15 | E29: =IFERROR(('bloco 02'!F15),"") | F29: ='bloco 02'!G15
A30: TREINO 02
B31: SETS | C31: REPS | D31: KG | E31: %1RM / PSE | F31: OBS
A32: ='bloco 02'!$B21 | B32: ='bloco 02'!C21 | C32: ='bloco 02'!D21 | D32: ='bloco 02'!E21 | E32: =IFERROR(('bloco 02'!F21),"") | F32: ='bloco 02'!G21
A33: ='bloco 02'!$B22 | B33: ='bloco 02'!C22 | C33: ='bloco 02'!D22 | D33: ='bloco 02'!E22 | E33: =IFERROR(('bloco 02'!F22),"") | F33: ='bloco 02'!G22
A34: ='bloco 02'!$B23 | B34: ='bloco 02'!C23 | C34: ='bloco 02'!D23 | D34: ='bloco 02'!E23 | E34: =IFERROR(('bloco 02'!F23),"") | F34: ='bloco 02'!G23
A35: ='bloco 02'!$B24 | B35: ='bloco 02'!C24 | C35: ='bloco 02'!D24 | D35: ='bloco 02'!E24 | E35: =IFERROR(('bloco 02'!F24),"") | F35: ='bloco 02'!G24
A36: ='bloco 02'!$B25 | B36: ='bloco 02'!C25 | C36: ='bloco 02'!D25 | D36: ='bloco 02'!E25 | E36: =IFERROR(('bloco 02'!F25),"") | F36: ='bloco 02'!G25
A37: ='bloco 02'!$B26 | B37: ='bloco 02'!C26 | C37: ='bloco 02'!D26 | D37: ='bloco 02'!E26 | E37: =IFERROR(('bloco 02'!F26),"") | F37: ='bloco 02'!G26
A38: ='bloco 02'!$B27 | B38: ='bloco 02'!C27 | C38: ='bloco 02'!D27 | D38: ='bloco 02'!E27 | E38: =IFERROR(('bloco 02'!F27),"") | F38: ='bloco 02'!G27
A39: ='bloco 02'!$B28 | B39: ='bloco 02'!C28 | C39: ='bloco 02'!D28 | D39: ='bloco 02'!E28 | E39: =IFERROR(('bloco 02'!F28),"") | F39: ='bloco 02'!G28
A40: ='bloco 02'!$B29 | B40: ='bloco 02'!C29 | C40: ='bloco 02'!D29 | D40: ='bloco 02'!E29 | E40: =IFERROR(('bloco 02'!F29),"") | F40: ='bloco 02'!G29
A41: ='bloco 02'!$B30 | B41: ='bloco 02'!C30 | C41: ='bloco 02'!D30 | D41: ='bloco 02'!E30 | E41: =IFERROR(('bloco 02'!F30),"") | F41: ='bloco 02'!G30
A42: TREINO 03
B43: SETS | C43: REPS | D43: KG | E43: %1RM / PSE | F43: OBS
A44: ='bloco 02'!$B36 | B44: ='bloco 02'!C36 | C44: ='bloco 02'!D36 | D44: ='bloco 02'!E36 | E44: =IFERROR(('bloco 02'!F36),"") | F44: ='bloco 02'!G36
A45: ='bloco 02'!$B37 | B45: ='bloco 02'!C37 | C45: ='bloco 02'!D37 | D45: ='bloco 02'!E37 | E45: =IFERROR(('bloco 02'!F37),"") | F45: ='bloco 02'!G37
A46: ='bloco 02'!$B38 | B46: ='bloco 02'!C38 | C46: ='bloco 02'!D38 | D46: ='bloco 02'!E38 | E46: =IFERROR(('bloco 02'!F38),"") | F46: ='bloco 02'!G38
...

Sheet bloco 02
A1: BLOCO 02
A3: TREINO 01 | C3: =macro!F6 | J3: =C3+7 | Q3: =J3+7 | X3: =Q3+7
C4: SETS | D4: REPS | E4: KG | F4: %1RM | G4: OBS | J4: SETS | K4: REPS | L4: KG | M4: %1RM | N4: OBS | Q4: SETS | R4: REPS | S4: KG | T4: %1RM | U4: OBS | X4: SETS | Y4: REPS | Z4: KG | AA4: %1RM | AB4: OBS
B5: exercícios | F5: pse | I5: exercícios | M5: pse | P5: exercícios | T5: pse | W5: exercícios | AA5: pse
F6: =IFERROR(__xludf.DUMMYFUNCTION("IFERROR($E6/INDEX(prs!$D$18:$D$24,MATCH(TRUE,ARRAYFORMULA(ISNUMBER(SEARCH(prs!$A$18:$A$24,$B6))),0)),"""")"),"") | M6: =IFERROR(__xludf.DUMMYFUNCTION("IFERROR($L6/INDEX(prs!$D$18:$D$24,MATCH(TRUE,ARRAYFORMULA(ISNUMBER(SEARCH(prs!$A$18:$A$24,$I6))),0)),"""")"),"") | T6: =IFERROR(__xludf.DUMMYFUNCTION("IFERROR($S6/INDEX(prs!$D$18:$D$24,MATCH(TRUE,ARRAYFORMULA(ISNUMBER(SEARCH(prs!$A$18:$A$24,$P6))),0)),"""")"),"") | AA6: =IFERROR(__xludf.DUMMYFUNCTION("IFERROR($Z6/INDEX(prs!$D$18:$D$24,MATCH(TRUE,ARRAYFORMULA(ISNUMBER(SEARCH(prs!$A$18:$A$24,$W6))),0)),"""")"),"")
F7: =IFERROR(__xludf.DUMMYFUNCTION("IFERROR($E7/INDEX(prs!$D$18:$D$24,MATCH(TRUE,ARRAYFORMULA(ISNUMBER(SEARCH(prs!$A$18:$A$24,$B7))),0)),"""")"),"") | M7: =IFERROR(__xludf.DUMMYFUNCTION("IFERROR($L7/INDEX(prs!$D$18:$D$24,MATCH(TRUE,ARRAYFORMULA(ISNUMBER(SEARCH(prs!$A$18:$A$24,$I7))),0)),"""")"),"") | T7: =IFERROR(__xludf.DUMMYFUNCTION("IFERROR($S7/INDEX(prs!$D$18:$D$24,MATCH(TRUE,ARRAYFORMULA(ISNUMBER(SEARCH(prs!$A$18:$A$24,$P7))),0)),"""")"),"") | AA7: =IFERROR(__xludf.DUMMYFUNCTION("IFERROR($Z7/INDEX(prs!$D$18:$D$24,MATCH(TRUE,ARRAYFORMULA(ISNUMBER(SEARCH(prs!$A$18:$A$24,$W7))),0)),"""")"),"")
F8: =IFERROR(__xludf.DUMMYFUNCTION("IFERROR($E8/INDEX(prs!$D$18:$D$24,MATCH(TRUE,ARRAYFORMULA(ISNUMBER(SEARCH(prs!$A$18:$A$24,$B8))),0)),"""")"),"") | M8: =IFERROR(__xludf.DUMMYFUNCTION("IFERROR($L8/INDEX(prs!$D$18:$D$24,MATCH(TRUE,ARRAYFORMULA(ISNUMBER(SEARCH(prs!$A$18:$A$24,$I8))),0)),"""")"),"") | T8: =IFERROR(__xludf.DUMMYFUNCTION("IFERROR($S8/INDEX(prs!$D$18:$D$24,MATCH(TRUE,ARRAYFORMULA(ISNUMBER(SEARCH(prs!$A$18:$A$24,$P8))),0)),"""")"),"") | AA8: =IFERROR(__xludf.DUMMYFUNCTION("IFERROR($Z8/INDEX(prs!$D$18:$D$24,MATCH(TRUE,ARRAYFORMULA(ISNUMBER(SEARCH(prs!$A$18:$A$24,$W8))),0)),"""")"),"")
F9: =IFERROR(__xludf.DUMMYFUNCTION("IFERROR($E9/INDEX(prs!$D$18:$D$24,MATCH(TRUE,ARRAYFORMULA(ISNUMBER(SEARCH(prs!$A$18:$A$24,$B9))),0)),"""")"),"") | M9: =IFERROR(__xludf.DUMMYFUNCTION("IFERROR($L9/INDEX(prs!$D$18:$D$24,MATCH(TRUE,ARRAYFORMULA(ISNUMBER(SEARCH(prs!$A$18:$A$24,$I9))),0)),"""")"),"") | T9: =IFERROR(__xludf.DUMMYFUNCTION("IFERROR($S9/INDEX(prs!$D$18:$D$24,MATCH(TRUE,ARRAYFORMULA(ISNUMBER(SEARCH(prs!$A$18:$A$24,$P9))),0)),"""")"),"") | AA9: =IFERROR(__xludf.DUMMYFUNCTION("IFERROR($Z9/INDEX(prs!$D$18:$D$24,MATCH(TRUE,ARRAYFORMULA(ISNUMBER(SEARCH(prs!$A$18:$A$24,$W9))),0)),"""")"),"")
F10: =IFERROR(__xludf.DUMMYFUNCTION("IFERROR($E10/INDEX(prs!$D$18:$D$24,MATCH(TRUE,ARRAYFORMULA(ISNUMBER(SEARCH(prs!$A$18:$A$24,$B10))),0)),"""")"),"") | M10: =IFERROR(__xludf.DUMMYFUNCTION("IFERROR($L10/INDEX(prs!$D$18:$D$24,MATCH(TRUE,ARRAYFORMULA(ISNUMBER(SEARCH(prs!$A$18:$A$24,$I10))),0)),"""")"),"") | T10: =IFERROR(__xludf.DUMMYFUNCTION("IFERROR($S10/INDEX(prs!$D$18:$D$24,MATCH(TRUE,ARRAYFORMULA(ISNUMBER(SEARCH(prs!$A$18:$A$24,$P10))),0)),"""")"),"") | AA10: =IFERROR(__xludf.DUMMYFUNCTION("IFERROR($Z10/INDEX(prs!$D$18:$D$24,MATCH(TRUE,ARRAYFORMULA(ISNUMBER(SEARCH(prs!$A$18:$A$24,$W10))),0)),"""")"),"")
F11: =IFERROR(__xludf.DUMMYFUNCTION("IFERROR($E11/INDEX(prs!$D$18:$D$24,MATCH(TRUE,ARRAYFORMULA(ISNUMBER(SEARCH(prs!$A$18:$A$24,$B11))),0)),"""")"),"") | M11: =IFERROR(__xludf.DUMMYFUNCTION("IFERROR($L11/INDEX(prs!$D$18:$D$24,MATCH(TRUE,ARRAYFORMULA(ISNUMBER(SEARCH(prs!$A$18:$A$24,$I11))),0)),"""")"),"") | T11: =IFERROR(__xludf.DUMMYFUNCTION("IFERROR($S11/INDEX(prs!$D$18:$D$24,MATCH(TRUE,ARRAYFORMULA(ISNUMBER(SEARCH(prs!$A$18:$A$24,$P11))),0)),"""")"),"") | AA11: =IFERROR(__xludf.DUMMYFUNCTION("IFERROR($Z11/INDEX(prs!$D$18:$D$24,MATCH(TRUE,ARRAYFORMULA(ISNUMBER(SEARCH(prs!$A$18:$A$24,$W11))),0)),"""")"),"")
F12: =IFERROR(__xludf.DUMMYFUNCTION("IFERROR($E12/INDEX(prs!$D$18:$D$24,MATCH(TRUE,ARRAYFORMULA(ISNUMBER(SEARCH(prs!$A$18:$A$24,$B12))),0)),"""")"),"") | M12: =IFERROR(__xludf.DUMMYFUNCTION("IFERROR($L12/INDEX(prs!$D$18:$D$24,MATCH(TRUE,ARRAYFORMULA(ISNUMBER(SEARCH(prs!$A$18:$A$24,$I12))),0)),"""")"),"") | T12: =IFERROR(__xludf.DUMMYFUNCTION("IFERROR($S12/INDEX(prs!$D$18:$D$24,MATCH(TRUE,ARRAYFORMULA(ISNUMBER(SEARCH(prs!$A$18:$A$24,$P12))),0)),"""")"),"") | AA12: =IFERROR(__xludf.DUMMYFUNCTION("IFERROR($Z12/INDEX(prs!$D$18:$D$24,MATCH(TRUE,ARRAYFORMULA(ISNUMBER(SEARCH(prs!$A$18:$A$24,$W12))),0)),"""")"),"")
F13: =IFERROR(__xludf.DUMMYFUNCTION("IFERROR($E13/INDEX(prs!$D$18:$D$24,MATCH(TRUE,ARRAYFORMULA(ISNUMBER(SEARCH(prs!$A$18:$A$24,$B13))),0)),"""")"),"") | M13: =IFERROR(__xludf.DUMMYFUNCTION("IFERROR($L13/INDEX(prs!$D$18:$D$24,MATCH(TRUE,ARRAYFORMULA(ISNUMBER(SEARCH(prs!$A$18:$A$24,$I13))),0)),"""")"),"") | T13: =IFERROR(__xludf.DUMMYFUNCTION("IFERROR($S13/INDEX(prs!$D$18:$D$24,MATCH(TRUE,ARRAYFORMULA(ISNUMBER(SEARCH(prs!$A$18:$A$24,$P13))),0)),"""")"),"") | AA13: =IFERROR(__xludf.DUMMYFUNCTION("IFERROR($Z13/INDEX(prs!$D$18:$D$24,MATCH(TRUE,ARRAYFORMULA(ISNUMBER(SEARCH(prs!$A$18:$A$24,$W13))),0)),"""")"),"")
F14: =IFERROR(__xludf.DUMMYFUNCTION("IFERROR($E14/INDEX(prs!$D$18:$D$24,MATCH(TRUE,ARRAYFORMULA(ISNUMBER(SEARCH(prs!$A$18:$A$24,$B14))),0)),"""")"),"") | M14: =IFERROR(__xludf.DUMMYFUNCTION("IFERROR($L14/INDEX(prs!$D$18:$D$24,MATCH(TRUE,ARRAYFORMULA(ISNUMBER(SEARCH(prs!$A$18:$A$24,$I14))),0)),"""")"),"") | T14: =IFERROR(__xludf.DUMMYFUNCTION("IFERROR($S14/INDEX(prs!$D$18:$D$24,MATCH(TRUE,ARRAYFORMULA(ISNUMBER(SEARCH(prs!$A$18:$A$24,$P14))),0)),"""")"),"") | AA14: =IFERROR(__xludf.DUMMYFUNCTION("IFERROR($Z14/INDEX(prs!$D$18:$D$24,MATCH(TRUE,ARRAYFORMULA(ISNUMBER(SEARCH(prs!$A$18:$A$24,$W14))),0)),"""")"),"")
F15: =IFERROR(__xludf.DUMMYFUNCTION("IFERROR($E15/INDEX(prs!$D$18:$D$24,MATCH(TRUE,ARRAYFORMULA(ISNUMBER(SEARCH(prs!$A$18:$A$24,$B15))),0)),"""")"),"") | M15: =IFERROR(__xludf.DUMMYFUNCTION("IFERROR($L15/INDEX(prs!$D$18:$D$24,MATCH(TRUE,ARRAYFORMULA(ISNUMBER(SEARCH(prs!$A$18:$A$24,$I15))),0)),"""")"),"") | T15: =IFERROR(__xludf.DUMMYFUNCTION("IFERROR($S15/INDEX(prs!$D$18:$D$24,MATCH(TRUE,ARRAYFORMULA(ISNUMBER(SEARCH(prs!$A$18:$A$24,$P15))),0)),"""")"),"") | AA15: =IFERROR(__xludf.DUMMYFUNCTION("IFERROR($Z15/INDEX(prs!$D$18:$D$24,MATCH(TRUE,ARRAYFORMULA(ISNUMBER(SEARCH(prs!$A$18:$A$24,$W15))),0)),"""")"),"")
C16: SEMANA 01 | J16: SEMANA 02 | Q16: SEMANA 03 | X16: SEMANA 04
A18: TREINO 02
C19: SETS | D19: REPS | E19: KG | F19: %1RM | G19: OBS | J19: SETS | K19: REPS | L19: KG | M19: %1RM | N19: OBS | Q19: SETS | R19: REPS | S19: KG | T19: %1RM | U19: OBS | X19: SETS | Y19: REPS | Z19: KG | AA19: %1RM | AB19: OBS
B20: exercícios | F20: pse | I20: exercícios | M20: pse | P20: exercícios | T20: pse | W20: exercícios | AA20: pse
F21: =IFERROR(__xludf.DUMMYFUNCTION("IFERROR($E21/INDEX(prs!$D$18:$D$24,MATCH(TRUE,ARRAYFORMULA(ISNUMBER(SEARCH(prs!$A$18:$A$24,$B21))),0)),"""")"),"") | M21: =IFERROR(__xludf.DUMMYFUNCTION("IFERROR($L21/INDEX(prs!$D$18:$D$24,MATCH(TRUE,ARRAYFORMULA(ISNUMBER(SEARCH(prs!$A$18:$A$24,$I21))),0)),"""")"),"") | T21: =IFERROR(__xludf.DUMMYFUNCTION("IFERROR($S21/INDEX(prs!$D$18:$D$24,MATCH(TRUE,ARRAYFORMULA(ISNUMBER(SEARCH(prs!$A$18:$A$24,$P21))),0)),"""")"),"") | AA21: =IFERROR(__xludf.DUMMYFUNCTION("IFERROR($Z21/INDEX(prs!$D$18:$D$24,MATCH(TRUE,ARRAYFORMULA(ISNUMBER(SEARCH(prs!$A$18:$A$24,$W21))),0)),"""")"),"")
F22: =IFERROR(__xludf.DUMMYFUNCTION("IFERROR($E22/INDEX(prs!$D$18:$D$24,MATCH(TRUE,ARRAYFORMULA(ISNUMBER(SEARCH(prs!$A$18:$A$24,$B22))),0)),"""")"),"") | M22: =IFERROR(__xludf.DUMMYFUNCTION("IFERROR($L22/INDEX(prs!$D$18:$D$24,MATCH(TRUE,ARRAYFORMULA(ISNUMBER(SEARCH(prs!$A$18:$A$24,$I22))),0)),"""")"),"") | T22: =IFERROR(__xludf.DUMMYFUNCTION("IFERROR($S22/INDEX(prs!$D$18:$D$24,MATCH(TRUE,ARRAYFORMULA(ISNUMBER(SEARCH(prs!$A$18:$A$24,$P22))),0)),"""")"),"") | AA22: =IFERROR(__xludf.DUMMYFUNCTION("IFERROR($Z22/INDEX(prs!$D$18:$D$24,MATCH(TRUE,ARRAYFORMULA(ISNUMBER(SEARCH(prs!$A$18:$A$24,$W22))),0)),"""")"),"")
F23: =IFERROR(__xludf.DUMMYFUNCTION("IFERROR($E23/INDEX(prs!$D$18:$D$24,MATCH(TRUE,ARRAYFORMULA(ISNUMBER(SEARCH(prs!$A$18:$A$24,$B23))),0)),"""")"),"") | M23: =IFERROR(__xludf.DUMMYFUNCTION("IFERROR($L23/INDEX(prs!$D$18:$D$24,MATCH(TRUE,ARRAYFORMULA(ISNUMBER(SEARCH(prs!$A$18:$A$24,$I23))),0)),"""")"),"") | T23: =IFERROR(__xludf.DUMMYFUNCTION("IFERROR($S23/INDEX(prs!$D$18:$D$24,MATCH(TRUE,ARRAYFORMULA(ISNUMBER(SEARCH(prs!$A$18:$A$24,$P23))),0)),"""")"),"") | AA23: =IFERROR(__xludf.DUMMYFUNCTION("IFERROR($Z23/INDEX(prs!$D$18:$D$24,MATCH(TRUE,ARRAYFORMULA(ISNUMBER(SEARCH(prs!$A$18:$A$24,$W23))),0)),"""")"),"")
F24: =IFERROR(__xludf.DUMMYFUNCTION("IFERROR($E24/INDEX(prs!$D$18:$D$24,MATCH(TRUE,ARRAYFORMULA(ISNUMBER(SEARCH(prs!$A$18:$A$24,$B24))),0)),"""")"),"") | M24: =IFERROR(__xludf.DUMMYFUNCTION("IFERROR($L24/INDEX(prs!$D$18:$D$24,MATCH(TRUE,ARRAYFORMULA(ISNUMBER(SEARCH(prs!$A$18:$A$24,$I24))),0)),"""")"),"") | T24: =IFERROR(__xludf.DUMMYFUNCTION("IFERROR($S24/INDEX(prs!$D$18:$D$24,MATCH(TRUE,ARRAYFORMULA(ISNUMBER(SEARCH(prs!$A$18:$A$24,$P24))),0)),"""")"),"") | AA24: =IFERROR(__xludf.DUMMYFUNCTION("IFERROR($Z24/INDEX(prs!$D$18:$D$24,MATCH(TRUE,ARRAYFORMULA(ISNUMBER(SEARCH(prs!$A$18:$A$24,$W24))),0)),"""")"),"")
F25: =IFERROR(__xludf.DUMMYFUNCTION("IFERROR($E25/INDEX(prs!$D$18:$D$24,MATCH(TRUE,ARRAYFORMULA(ISNUMBER(SEARCH(prs!$A$18:$A$24,$B25))),0)),"""")"),"") | M25: =IFERROR(__xludf.DUMMYFUNCTION("IFERROR($L25/INDEX(prs!$D$18:$D$24,MATCH(TRUE,ARRAYFORMULA(ISNUMBER(SEARCH(prs!$A$18:$A$24,$I25))),0)),"""")"),"") | T25: =IFERROR(__xludf.DUMMYFUNCTION("IFERROR($S25/INDEX(prs!$D$18:$D$24,MATCH(TRUE,ARRAYFORMULA(ISNUMBER(SEARCH(prs!$A$18:$A$24,$P25))),0)),"""")"),"") | AA25: =IFERROR(__xludf.DUMMYFUNCTION("IFERROR($Z25/INDEX(prs!$D$18:$D$24,MATCH(TRUE,ARRAYFORMULA(ISNUMBER(SEARCH(prs!$A$18:$A$24,$W25))),0)),"""")"),"")
F26: =IFERROR(__xludf.DUMMYFUNCTION("IFERROR($E26/INDEX(prs!$D$18:$D$24,MATCH(TRUE,ARRAYFORMULA(ISNUMBER(SEARCH(prs!$A$18:$A$24,$B26))),0)),"""")"),"") | M26: =IFERROR(__xludf.DUMMYFUNCTION("IFERROR($L26/INDEX(prs!$D$18:$D$24,MATCH(TRUE,ARRAYFORMULA(ISNUMBER(SEARCH(prs!$A$18:$A$24,$I26))),0)),"""")"),"") | T26: =IFERROR(__xludf.DUMMYFUNCTION("IFERROR($S26/INDEX(prs!$D$18:$D$24,MATCH(TRUE,ARRAYFORMULA(ISNUMBER(SEARCH(prs!$A$18:$A$24,$P26))),0)),"""")"),"") | AA26: =IFERROR(__xludf.DUMMYFUNCTION("IFERROR($Z26/INDEX(prs!$D$18:$D$24,MATCH(TRUE,ARRAYFORMULA(ISNUMBER(SEARCH(prs!$A$18:$A$24,$W26))),0)),"""")"),"")
F27: =IFERROR(__xludf.DUMMYFUNCTION("IFERROR($E27/INDEX(prs!$D$18:$D$24,MATCH(TRUE,ARRAYFORMULA(ISNUMBER(SEARCH(prs!$A$18:$A$24,$B27))),0)),"""")"),"") | M27: =IFERROR(__xludf.DUMMYFUNCTION("IFERROR($L27/INDEX(prs!$D$18:$D$24,MATCH(TRUE,ARRAYFORMULA(ISNUMBER(SEARCH(prs!$A$18:$A$24,$I27))),0)),"""")"),"") | T27: =IFERROR(__xludf.DUMMYFUNCTION("IFERROR($S27/INDEX(prs!$D$18:$D$24,MATCH(TRUE,ARRAYFORMULA(ISNUMBER(SEARCH(prs!$A$18:$A$24,$P27))),0)),"""")"),"") | AA27: =IFERROR(__xludf.DUMMYFUNCTION("IFERROR($Z27/INDEX(prs!$D$18:$D$24,MATCH(TRUE,ARRAYFORMULA(ISNUMBER(SEARCH(prs!$A$18:$A$24,$W27))),0)),"""")"),"")
F28: =IFERROR(__xludf.DUMMYFUNCTION("IFERROR($E28/INDEX(prs!$D$18:$D$24,MATCH(TRUE,ARRAYFORMULA(ISNUMBER(SEARCH(prs!$A$18:$A$24,$B28))),0)),"""")"),"") | M28: =IFERROR(__xludf.DUMMYFUNCTION("IFERROR($L28/INDEX(prs!$D$18:$D$24,MATCH(TRUE,ARRAYFORMULA(ISNUMBER(SEARCH(prs!$A$18:$A$24,$I28))),0)),"""")"),"") | T28: =IFERROR(__xludf.DUMMYFUNCTION("IFERROR($S28/INDEX(prs!$D$18:$D$24,MATCH(TRUE,ARRAYFORMULA(ISNUMBER(SEARCH(prs!$A$18:$A$24,$P28))),0)),"""")"),"") | AA28: =IFERROR(__xludf.DUMMYFUNCTION("IFERROR($Z28/INDEX(prs!$D$18:$D$24,MATCH(TRUE,ARRAYFORMULA(ISNUMBER(SEARCH(prs!$A$18:$A$24,$W28))),0)),"""")"),"")
F29: =IFERROR(__xludf.DUMMYFUNCTION("IFERROR($E29/INDEX(prs!$D$18:$D$24,MATCH(TRUE,ARRAYFORMULA(ISNUMBER(SEARCH(prs!$A$18:$A$24,$B29))),0)),"""")"),"") | M29: =IFERROR(__xludf.DUMMYFUNCTION("IFERROR($L29/INDEX(prs!$D$18:$D$24,MATCH(TRUE,ARRAYFORMULA(ISNUMBER(SEARCH(prs!$A$18:$A$24,$I29))),0)),"""")"),"") | T29: =IFERROR(__xludf.DUMMYFUNCTION("IFERROR($S29/INDEX(prs!$D$18:$D$24,MATCH(TRUE,ARRAYFORMULA(ISNUMBER(SEARCH(prs!$A$18:$A$24,$P29))),0)),"""")"),"") | AA29: =IFERROR(__xludf.DUMMYFUNCTION("IFERROR($Z29/INDEX(prs!$D$18:$D$24,MATCH(TRUE,ARRAYFORMULA(ISNUMBER(SEARCH(prs!$A$18:$A$24,$W29))),0)),"""")"),"")
F30: =IFERROR(__xludf.DUMMYFUNCTION("IFERROR($E30/INDEX(prs!$D$18:$D$24,MATCH(TRUE,ARRAYFORMULA(ISNUMBER(SEARCH(prs!$A$18:$A$24,$B30))),0)),"""")"),"") | M30: =IFERROR(__xludf.DUMMYFUNCTION("IFERROR($L30/INDEX(prs!$D$18:$D$24,MATCH(TRUE,ARRAYFORMULA(ISNUMBER(SEARCH(prs!$A$18:$A$24,$I30))),0)),"""")"),"") | T30: =IFERROR(__xludf.DUMMYFUNCTION("IFERROR($S30/INDEX(prs!$D$18:$D$24,MATCH(TRUE,ARRAYFORMULA(ISNUMBER(SEARCH(prs!$A$18:$A$24,$P30))),0)),"""")"),"") | AA30: =IFERROR(__xludf.DUMMYFUNCTION("IFERROR($Z30/INDEX(prs!$D$18:$D$24,MATCH(TRUE,ARRAYFORMULA(ISNUMBER(SEARCH(prs!$A$18:$A$24,$W30))),0)),"""")"),"")
C31: SEMANA 01 | J31: SEMANA 02 | Q31: SEMANA 03 | X31: SEMANA 04
A33: TREINO 03
C34: SETS | D34: REPS | E34: KG | F34: %1RM | G34: OBS | J34: SETS | K34: REPS | L34: KG | M34: %1RM | N34: OBS | Q34: SETS | R34: REPS | S34: KG | T34: %1RM | U34: OBS | X34: SETS | Y34: REPS | Z34: KG | AA34: %1RM | AB34: OBS
B35: exercícios | F35: pse | I35: exercícios | M35: pse | P35: exercícios | T35: pse | W35: exercícios | AA35: pse
F36: =IFERROR(__xludf.DUMMYFUNCTION("IFERROR($E36/INDEX(prs!$D$18:$D$24,MATCH(TRUE,ARRAYFORMULA(ISNUMBER(SEARCH(prs!$A$18:$A$24,$B36))),0)),"""")"),"") | M36: =IFERROR(__xludf.DUMMYFUNCTION("IFERROR($L36/INDEX(prs!$D$18:$D$24,MATCH(TRUE,ARRAYFORMULA(ISNUMBER(SEARCH(prs!$A$18:$A$24,$I36))),0)),"""")"),"") | T36: =IFERROR(__xludf.DUMMYFUNCTION("IFERROR($S36/INDEX(prs!$D$18:$D$24,MATCH(TRUE,ARRAYFORMULA(ISNUMBER(SEARCH(prs!$A$18:$A$24,$P36))),0)),"""")"),"") | AA36: =IFERROR(__xludf.DUMMYFUNCTION("IFERROR($Z36/INDEX(prs!$D$18:$D$24,MATCH(TRUE,ARRAYFORMULA(ISNUMBER(SEARCH(prs!$A$18:$A$24,$W36))),0)),"""")"),"")
F37: =IFERROR(__xludf.DUMMYFUNCTION("IFERROR($E37/INDEX(prs!$D$18:$D$24,MATCH(TRUE,ARRAYFORMULA(ISNUMBER(SEARCH(prs!$A$18:$A$24,$B37))),0)),"""")"),"") | M37: =IFERROR(__xludf.DUMMYFUNCTION("IFERROR($L37/INDEX(prs!$D$18:$D$24,MATCH(TRUE,ARRAYFORMULA(ISNUMBER(SEARCH(prs!$A$18:$A$24,$I37))),0)),"""")"),"") | T37: =IFERROR(__xludf.DUMMYFUNCTION("IFERROR($S37/INDEX(prs!$D$18:$D$24,MATCH(TRUE,ARRAYFORMULA(ISNUMBER(SEARCH(prs!$A$18:$A$24,$P37))),0)),"""")"),"") | AA37: =IFERROR(__xludf.DUMMYFUNCTION("IFERROR($Z37/INDEX(prs!$D$18:$D$24,MATCH(TRUE,ARRAYFORMULA(ISNUMBER(SEARCH(prs!$A$18:$A$24,$W37))),0)),"""")"),"")
F38: =IFERROR(__xludf.DUMMYFUNCTION("IFERROR($E38/INDEX(prs!$D$18:$D$24,MATCH(TRUE,ARRAYFORMULA(ISNUMBER(SEARCH(prs!$A$18:$A$24,$B38))),0)),"""")"),"") | M38: =IFERROR(__xludf.DUMMYFUNCTION("IFERROR($L38/INDEX(prs!$D$18:$D$24,MATCH(TRUE,ARRAYFORMULA(ISNUMBER(SEARCH(prs!$A$18:$A$24,$I38))),0)),"""")"),"") | T38: =IFERROR(__xludf.DUMMYFUNCTION("IFERROR($S38/INDEX(prs!$D$18:$D$24,MATCH(TRUE,ARRAYFORMULA(ISNUMBER(SEARCH(prs!$A$18:$A$24,$P38))),0)),"""")"),"") | AA38: =IFERROR(__xludf.DUMMYFUNCTION("IFERROR($Z38/INDEX(prs!$D$18:$D$24,MATCH(TRUE,ARRAYFORMULA(ISNUMBER(SEARCH(prs!$A$18:$A$24,$W38))),0)),"""")"),"")
F39: =IFERROR(__xludf.DUMMYFUNCTION("IFERROR($E39/INDEX(prs!$D$18:$D$24,MATCH(TRUE,ARRAYFORMULA(ISNUMBER(SEARCH(prs!$A$18:$A$24,$B39))),0)),"""")"),"") | M39: =IFERROR(__xludf.DUMMYFUNCTION("IFERROR($L39/INDEX(prs!$D$18:$D$24,MATCH(TRUE,ARRAYFORMULA(ISNUMBER(SEARCH(prs!$A$18:$A$24,$I39))),0)),"""")"),"") | T39: =IFERROR(__xludf.DUMMYFUNCTION("IFERROR($S39/INDEX(prs!$D$18:$D$24,MATCH(TRUE,ARRAYFORMULA(ISNUMBER(SEARCH(prs!$A$18:$A$24,$P39))),0)),"""")"),"") | AA39: =IFERROR(__xludf.DUMMYFUNCTION("IFERROR($Z39/INDEX(prs!$D$18:$D$24,MATCH(TRUE,ARRAYFORMULA(ISNUMBER(SEARCH(prs!$A$18:$A$24,$W39))),0)),"""")"),"")
F40: =IFERROR(__xludf.DUMMYFUNCTION("IFERROR($E40/INDEX(prs!$D$18:$D$24,MATCH(TRUE,ARRAYFORMULA(ISNUMBER(SEARCH(prs!$A$18:$A$24,$B40))),0)),"""")"),"") | M40: =IFERROR(__xludf.DUMMYFUNCTION("IFERROR($L40/INDEX(prs!$D$18:$D$24,MATCH(TRUE,ARRAYFORMULA(ISNUMBER(SEARCH(prs!$A$18:$A$24,$I40))),0)),"""")"),"") | T40: =IFERROR(__xludf.DUMMYFUNCTION("IFERROR($S40/INDEX(prs!$D$18:$D$24,MATCH(TRUE,ARRAYFORMULA(ISNUMBER(SEARCH(prs!$A$18:$A$24,$P40))),0)),"""")"),"") | AA40: =IFERROR(__xludf.DUMMYFUNCTION("IFERROR($Z40/INDEX(prs!$D$18:$D$24,MATCH(TRUE,ARRAYFORMULA(ISNUMBER(SEARCH(prs!$A$18:$A$24,$W40))),0)),"""")"),"")
F41: =IFERROR(__xludf.DUMMYFUNCTION("IFERROR($E41/INDEX(prs!$D$18:$D$24,MATCH(TRUE,ARRAYFORMULA(ISNUMBER(SEARCH(prs!$A$18:$A$24,$B41))),0)),"""")"),"") | M41: =IFERROR(__xludf.DUMMYFUNCTION("IFERROR($L41/INDEX(prs!$D$18:$D$24,MATCH(TRUE,ARRAYFORMULA(ISNUMBER(SEARCH(prs!$A$18:$A$24,$I41))),0)),"""")"),"") | T41: =IFERROR(__xludf.DUMMYFUNCTION("IFERROR($S41/INDEX(prs!$D$18:$D$24,MATCH(TRUE,ARRAYFORMULA(ISNUMBER(SEARCH(prs!$A$18:$A$24,$P41))),0)),"""")"),"") | AA41: =IFERROR(__xludf.DUMMYFUNCTION("IFERROR($Z41/INDEX(prs!$D$18:$D$24,MATCH(TRUE,ARRAYFORMULA(ISNUMBER(SEARCH(prs!$A$18:$A$24,$W41))),0)),"""")"),"")
F42: =IFERROR(__xludf.DUMMYFUNCTION("IFERROR($E42/INDEX(prs!$D$18:$D$24,MATCH(TRUE,ARRAYFORMULA(ISNUMBER(SEARCH(prs!$A$18:$A$24,$B42))),0)),"""")"),"") | M42: =IFERROR(__xludf.DUMMYFUNCTION("IFERROR($L42/INDEX(prs!$D$18:$D$24,MATCH(TRUE,ARRAYFORMULA(ISNUMBER(SEARCH(prs!$A$18:$A$24,$I42))),0)),"""")"),"") | T42: =IFERROR(__xludf.DUMMYFUNCTION("IFERROR($S42/INDEX(prs!$D$18:$D$24,MATCH(TRUE,ARRAYFORMULA(ISNUMBER(SEARCH(prs!$A$18:$A$24,$P42))),0)),"""")"),"") | AA42: =IFERROR(__xludf.DUMMYFUNCTION("IFERROR($Z42/INDEX(prs!$D$18:$D$24,MATCH(TRUE,ARRAYFORMULA(ISNUMBER(SEARCH(prs!$A$18:$A$24,$W42))),0)),"""")"),"")
F43: =IFERROR(__xludf.DUMMYFUNCTION("IFERROR($E43/INDEX(prs!$D$18:$D$24,MATCH(TRUE,ARRAYFORMULA(ISNUMBER(SEARCH(prs!$A$18:$A$24,$B43))),0)),"""")"),"") | M43: =IFERROR(__xludf.DUMMYFUNCTION("IFERROR($L43/INDEX(prs!$D$18:$D$24,MATCH(TRUE,ARRAYFORMULA(ISNUMBER(SEARCH(prs!$A$18:$A$24,$I43))),0)),"""")"),"") | T43: =IFERROR(__xludf.DUMMYFUNCTION("IFERROR($S43/INDEX(prs!$D$18:$D$24,MATCH(TRUE,ARRAYFORMULA(ISNUMBER(SEARCH(prs!$A$18:$A$24,$P43))),0)),"""")"),"") | AA43: =IFERROR(__xludf.DUMMYFUNCTION("IFERROR($Z43/INDEX(prs!$D$18:$D$24,MATCH(TRUE,ARRAYFORMULA(ISNUMBER(SEARCH(prs!$A$18:$A$24,$W43))),0)),"""")"),"")
...

Sheet aluno 03
B1: PLANILHA DE TREINAMENTO
B2: NOME | C2: ='aluno 01'!C2
B3: OBJETIVO | C3: ='aluno 01'!C3
B5: SEGUNDA | C5: TERÇA | D5: QUARTA | E5: QUINTA | F5: SEXTA
B6: ='aluno 01'!B6 | C6: ='aluno 01'!C6 | D6: ='aluno 01'!D6 | E6: ='aluno 01'!E6 | F6: ='aluno 01'!F6
A8: OBS
A9: ='aluno 01'!A9
A11: AQC
B12: SETS | C12: REPS / TEMPO | D12: KG | E12: OBS
A16: ='bloco 03'!C3
A17: SEMANA 01
A18: TREINO 01
B19: SETS | C19: REPS | D19: KG | E19: %1RM / PSE | F19: OBS
A20: ='bloco 03'!$B6 | B20: ='bloco 03'!C6 | C20: ='bloco 03'!D6 | D20: ='bloco 03'!E6 | E20: =IFERROR(('bloco 03'!F6),"") | F20: ='bloco 03'!G6
A21: ='bloco 03'!$B7 | B21: ='bloco 03'!C7 | C21: ='bloco 03'!D7 | D21: ='bloco 03'!E7 | E21: =IFERROR(('bloco 03'!F7),"") | F21: ='bloco 03'!G7
A22: ='bloco 03'!$B8 | B22: ='bloco 03'!C8 | C22: ='bloco 03'!D8 | D22: ='bloco 03'!E8 | E22: =IFERROR(('bloco 03'!F8),"") | F22: ='bloco 03'!G8
A23: ='bloco 03'!$B9 | B23: ='bloco 03'!C9 | C23: ='bloco 03'!D9 | D23: ='bloco 03'!E9 | E23: =IFERROR(('bloco 03'!F9),"") | F23: ='bloco 03'!G9
A24: ='bloco 03'!$B10 | B24: ='bloco 03'!C10 | C24: ='bloco 03'!D10 | D24: ='bloco 03'!E10 | E24: =IFERROR(('bloco 03'!F10),"") | F24: ='bloco 03'!G10
A25: ='bloco 03'!$B11 | B25: ='bloco 03'!C11 | C25: ='bloco 03'!D11 | D25: ='bloco 03'!E11 | E25: =IFERROR(('bloco 03'!F11),"") | F25: ='bloco 03'!G11
A26: ='bloco 03'!$B12 | B26: ='bloco 03'!C12 | C26: ='bloco 03'!D12 | D26: ='bloco 03'!E12 | E26: =IFERROR(('bloco 03'!F12),"") | F26: ='bloco 03'!G12
A27: ='bloco 03'!$B13 | B27: ='bloco 03'!C13 | C27: ='bloco 03'!D13 | D27: ='bloco 03'!E13 | E27: =IFERROR(('bloco 03'!F13),"") | F27: ='bloco 03'!G13
A28: ='bloco 03'!$B14 | B28: ='bloco 03'!C14 | C28: ='bloco 03'!D14 | D28: ='bloco 03'!E14 | E28: =IFERROR(('bloco 03'!F14),"") | F28: ='bloco 03'!G14
A29: ='bloco 03'!$B15 | B29: ='bloco 03'!C15 | C29: ='bloco 03'!D15 | D29: ='bloco 03'!E15 | E29: =IFERROR(('bloco 03'!F15),"") | F29: ='bloco 03'!G15
A30: TREINO 02
B31: SETS | C31: REPS | D31: KG | E31: %1RM / PSE | F31: OBS
A32: ='bloco 03'!$B21 | B32: ='bloco 03'!C21 | C32: ='bloco 03'!D21 | D32: ='bloco 03'!E21 | E32: =IFERROR(('bloco 03'!F21),"") | F32: ='bloco 03'!G21
A33: ='bloco 03'!$B22 | B33: ='bloco 03'!C22 | C33: ='bloco 03'!D22 | D33: ='bloco 03'!E22 | E33: =IFERROR(('bloco 03'!F22),"") | F33: ='bloco 03'!G22
A34: ='bloco 03'!$B23 | B34: ='bloco 03'!C23 | C34: ='bloco 03'!D23 | D34: ='bloco 03'!E23 | E34: =IFERROR(('bloco 03'!F23),"") | F34: ='bloco 03'!G23
A35: ='bloco 03'!$B24 | B35: ='bloco 03'!C24 | C35: ='bloco 03'!D24 | D35: ='bloco 03'!E24 | E35: =IFERROR(('bloco 03'!F24),"") | F35: ='bloco 03'!G24
A36: ='bloco 03'!$B25 | B36: ='bloco 03'!C25 | C36: ='bloco 03'!D25 | D36: ='bloco 03'!E25 | E36: =IFERROR(('bloco 03'!F25),"") | F36: ='bloco 03'!G25
A37: ='bloco 03'!$B26 | B37: ='bloco 03'!C26 | C37: ='bloco 03'!D26 | D37: ='bloco 03'!E26 | E37: =IFERROR(('bloco 03'!F26),"") | F37: ='bloco 03'!G26
A38: ='bloco 03'!$B27 | B38: ='bloco 03'!C27 | C38: ='bloco 03'!D27 | D38: ='bloco 03'!E27 | E38: =IFERROR(('bloco 03'!F27),"") | F38: ='bloco 03'!G27
A39: ='bloco 03'!$B28 | B39: ='bloco 03'!C28 | C39: ='bloco 03'!D28 | D39: ='bloco 03'!E28 | E39: =IFERROR(('bloco 03'!F28),"") | F39: ='bloco 03'!G28
A40: ='bloco 03'!$B29 | B40: ='bloco 03'!C29 | C40: ='bloco 03'!D29 | D40: ='bloco 03'!E29 | E40: =IFERROR(('bloco 03'!F29),"") | F40: ='bloco 03'!G29
A41: ='bloco 03'!$B30 | B41: ='bloco 03'!C30 | C41: ='bloco 03'!D30 | D41: ='bloco 03'!E30 | E41: =IFERROR(('bloco 03'!F30),"") | F41: ='bloco 03'!G30
A42: TREINO 03
B43: SETS | C43: REPS | D43: KG | E43: %1RM / PSE | F43: OBS
A44: ='bloco 03'!$B36 | B44: ='bloco 03'!C36 | C44: ='bloco 03'!D36 | D44: ='bloco 03'!E36 | E44: =IFERROR(('bloco 03'!F36),"") | F44: ='bloco 03'!G36
A45: ='bloco 03'!$B37 | B45: ='bloco 03'!C37 | C45: ='bloco 03'!D37 | D45: ='bloco 03'!E37 | E45: =IFERROR(('bloco 03'!F37),"") | F45: ='bloco 03'!G37
A46: ='bloco 03'!$B38 | B46: ='bloco 03'!C38 | C46: ='bloco 03'!D38 | D46: ='bloco 03'!E38 | E46: =IFERROR(('bloco 03'!F38),"") | F46: ='bloco 03'!G38
...

Sheet bloco 03
A1: BLOCO 03
A3: TREINO 01 | C3: =macro!J6 | J3: =C3+7 | Q3: =J3+7 | X3: =Q3+7
C4: SETS | D4: REPS | E4: KG | F4: %1RM | G4: OBS | J4: SETS | K4: REPS | L4: KG | M4: %1RM | N4: OBS | Q4: SETS | R4: REPS | S4: KG | T4: %1RM | U4: OBS | X4: SETS | Y4: REPS | Z4: KG | AA4: %1RM | AB4: OBS
B5: exercícios | F5: pse | I5: exercícios | M5: pse | P5: exercícios | T5: pse | W5: exercícios | AA5: pse
F6: =IFERROR(__xludf.DUMMYFUNCTION("IFERROR($E6/INDEX(prs!$D$30:$D$36,MATCH(TRUE,ARRAYFORMULA(ISNUMBER(SEARCH(prs!$A$30:$A$36,$B6))),0)),"""")"),"") | M6: =IFERROR(__xludf.DUMMYFUNCTION("IFERROR($L6/INDEX(prs!$D$30:$D$36,MATCH(TRUE,ARRAYFORMULA(ISNUMBER(SEARCH(prs!$A$30:$A$36,$I6))),0)),"""")"),"") | T6: =IFERROR(__xludf.DUMMYFUNCTION("IFERROR($S6/INDEX(prs!$D$30:$D$36,MATCH(TRUE,ARRAYFORMULA(ISNUMBER(SEARCH(prs!$A$30:$A$36,$P6))),0)),"""")"),"") | AA6: =IFERROR(__xludf.DUMMYFUNCTION("IFERROR($Z6/INDEX(prs!$D$30:$D$36,MATCH(TRUE,ARRAYFORMULA(ISNUMBER(SEARCH(prs!$A$30:$A$36,$W6))),0)),"""")"),"")
F7: =IFERROR(__xludf.DUMMYFUNCTION("IFERROR($E7/INDEX(prs!$D$30:$D$36,MATCH(TRUE,ARRAYFORMULA(ISNUMBER(SEARCH(prs!$A$30:$A$36,$B7))),0)),"""")"),"") | M7: =IFERROR(__xludf.DUMMYFUNCTION("IFERROR($L7/INDEX(prs!$D$30:$D$36,MATCH(TRUE,ARRAYFORMULA(ISNUMBER(SEARCH(prs!$A$30:$A$36,$I7))),0)),"""")"),"") | T7: =IFERROR(__xludf.DUMMYFUNCTION("IFERROR($S7/INDEX(prs!$D$30:$D$36,MATCH(TRUE,ARRAYFORMULA(ISNUMBER(SEARCH(prs!$A$30:$A$36,$P7))),0)),"""")"),"") | AA7: =IFERROR(__xludf.DUMMYFUNCTION("IFERROR($Z7/INDEX(prs!$D$30:$D$36,MATCH(TRUE,ARRAYFORMULA(ISNUMBER(SEARCH(prs!$A$30:$A$36,$W7))),0)),"""")"),"")
F8: =IFERROR(__xludf.DUMMYFUNCTION("IFERROR($E8/INDEX(prs!$D$30:$D$36,MATCH(TRUE,ARRAYFORMULA(ISNUMBER(SEARCH(prs!$A$30:$A$36,$B8))),0)),"""")"),"") | M8: =IFERROR(__xludf.DUMMYFUNCTION("IFERROR($L8/INDEX(prs!$D$30:$D$36,MATCH(TRUE,ARRAYFORMULA(ISNUMBER(SEARCH(prs!$A$30:$A$36,$I8))),0)),"""")"),"") | T8: =IFERROR(__xludf.DUMMYFUNCTION("IFERROR($S8/INDEX(prs!$D$30:$D$36,MATCH(TRUE,ARRAYFORMULA(ISNUMBER(SEARCH(prs!$A$30:$A$36,$P8))),0)),"""")"),"") | AA8: =IFERROR(__xludf.DUMMYFUNCTION("IFERROR($Z8/INDEX(prs!$D$30:$D$36,MATCH(TRUE,ARRAYFORMULA(ISNUMBER(SEARCH(prs!$A$30:$A$36,$W8))),0)),"""")"),"")
F9: =IFERROR(__xludf.DUMMYFUNCTION("IFERROR($E9/INDEX(prs!$D$30:$D$36,MATCH(TRUE,ARRAYFORMULA(ISNUMBER(SEARCH(prs!$A$30:$A$36,$B9))),0)),"""")"),"") | M9: =IFERROR(__xludf.DUMMYFUNCTION("IFERROR($L9/INDEX(prs!$D$30:$D$36,MATCH(TRUE,ARRAYFORMULA(ISNUMBER(SEARCH(prs!$A$30:$A$36,$I9))),0)),"""")"),"") | T9: =IFERROR(__xludf.DUMMYFUNCTION("IFERROR($S9/INDEX(prs!$D$30:$D$36,MATCH(TRUE,ARRAYFORMULA(ISNUMBER(SEARCH(prs!$A$30:$A$36,$P9))),0)),"""")"),"") | AA9: =IFERROR(__xludf.DUMMYFUNCTION("IFERROR($Z9/INDEX(prs!$D$30:$D$36,MATCH(TRUE,ARRAYFORMULA(ISNUMBER(SEARCH(prs!$A$30:$A$36,$W9))),0)),"""")"),"")
F10: =IFERROR(__xludf.DUMMYFUNCTION("IFERROR($E10/INDEX(prs!$D$30:$D$36,MATCH(TRUE,ARRAYFORMULA(ISNUMBER(SEARCH(prs!$A$30:$A$36,$B10))),0)),"""")"),"") | M10: =IFERROR(__xludf.DUMMYFUNCTION("IFERROR($L10/INDEX(prs!$D$30:$D$36,MATCH(TRUE,ARRAYFORMULA(ISNUMBER(SEARCH(prs!$A$30:$A$36,$I10))),0)),"""")"),"") | T10: =IFERROR(__xludf.DUMMYFUNCTION("IFERROR($S10/INDEX(prs!$D$30:$D$36,MATCH(TRUE,ARRAYFORMULA(ISNUMBER(SEARCH(prs!$A$30:$A$36,$P10))),0)),"""")"),"") | AA10: =IFERROR(__xludf.DUMMYFUNCTION("IFERROR($Z10/INDEX(prs!$D$30:$D$36,MATCH(TRUE,ARRAYFORMULA(ISNUMBER(SEARCH(prs!$A$30:$A$36,$W10))),0)),"""")"),"")
F11: =IFERROR(__xludf.DUMMYFUNCTION("IFERROR($E11/INDEX(prs!$D$30:$D$36,MATCH(TRUE,ARRAYFORMULA(ISNUMBER(SEARCH(prs!$A$30:$A$36,$B11))),0)),"""")"),"") | M11: =IFERROR(__xludf.DUMMYFUNCTION("IFERROR($L11/INDEX(prs!$D$30:$D$36,MATCH(TRUE,ARRAYFORMULA(ISNUMBER(SEARCH(prs!$A$30:$A$36,$I11))),0)),"""")"),"") | T11: =IFERROR(__xludf.DUMMYFUNCTION("IFERROR($S11/INDEX(prs!$D$30:$D$36,MATCH(TRUE,ARRAYFORMULA(ISNUMBER(SEARCH(prs!$A$30:$A$36,$P11))),0)),"""")"),"") | AA11: =IFERROR(__xludf.DUMMYFUNCTION("IFERROR($Z11/INDEX(prs!$D$30:$D$36,MATCH(TRUE,ARRAYFORMULA(ISNUMBER(SEARCH(prs!$A$30:$A$36,$W11))),0)),"""")"),"")
F12: =IFERROR(__xludf.DUMMYFUNCTION("IFERROR($E12/INDEX(prs!$D$30:$D$36,MATCH(TRUE,ARRAYFORMULA(ISNUMBER(SEARCH(prs!$A$30:$A$36,$B12))),0)),"""")"),"") | M12: =IFERROR(__xludf.DUMMYFUNCTION("IFERROR($L12/INDEX(prs!$D$30:$D$36,MATCH(TRUE,ARRAYFORMULA(ISNUMBER(SEARCH(prs!$A$30:$A$36,$I12))),0)),"""")"),"") | T12: =IFERROR(__xludf.DUMMYFUNCTION("IFERROR($S12/INDEX(prs!$D$30:$D$36,MATCH(TRUE,ARRAYFORMULA(ISNUMBER(SEARCH(prs!$A$30:$A$36,$P12))),0)),"""")"),"") | AA12: =IFERROR(__xludf.DUMMYFUNCTION("IFERROR($Z12/INDEX(prs!$D$30:$D$36,MATCH(TRUE,ARRAYFORMULA(ISNUMBER(SEARCH(prs!$A$30:$A$36,$W12))),0)),"""")"),"")
F13: =IFERROR(__xludf.DUMMYFUNCTION("IFERROR($E13/INDEX(prs!$D$30:$D$36,MATCH(TRUE,ARRAYFORMULA(ISNUMBER(SEARCH(prs!$A$30:$A$36,$B13))),0)),"""")"),"") | M13: =IFERROR(__xludf.DUMMYFUNCTION("IFERROR($L13/INDEX(prs!$D$30:$D$36,MATCH(TRUE,ARRAYFORMULA(ISNUMBER(SEARCH(prs!$A$30:$A$36,$I13))),0)),"""")"),"") | T13: =IFERROR(__xludf.DUMMYFUNCTION("IFERROR($S13/INDEX(prs!$D$30:$D$36,MATCH(TRUE,ARRAYFORMULA(ISNUMBER(SEARCH(prs!$A$30:$A$36,$P13))),0)),"""")"),"") | AA13: =IFERROR(__xludf.DUMMYFUNCTION("IFERROR($Z13/INDEX(prs!$D$30:$D$36,MATCH(TRUE,ARRAYFORMULA(ISNUMBER(SEARCH(prs!$A$30:$A$36,$W13))),0)),"""")"),"")
F14: =IFERROR(__xludf.DUMMYFUNCTION("IFERROR($E14/INDEX(prs!$D$30:$D$36,MATCH(TRUE,ARRAYFORMULA(ISNUMBER(SEARCH(prs!$A$30:$A$36,$B14))),0)),"""")"),"") | M14: =IFERROR(__xludf.DUMMYFUNCTION("IFERROR($L14/INDEX(prs!$D$30:$D$36,MATCH(TRUE,ARRAYFORMULA(ISNUMBER(SEARCH(prs!$A$30:$A$36,$I14))),0)),"""")"),"") | T14: =IFERROR(__xludf.DUMMYFUNCTION("IFERROR($S14/INDEX(prs!$D$30:$D$36,MATCH(TRUE,ARRAYFORMULA(ISNUMBER(SEARCH(prs!$A$30:$A$36,$P14))),0)),"""")"),"") | AA14: =IFERROR(__xludf.DUMMYFUNCTION("IFERROR($Z14/INDEX(prs!$D$30:$D$36,MATCH(TRUE,ARRAYFORMULA(ISNUMBER(SEARCH(prs!$A$30:$A$36,$W14))),0)),"""")"),"")
F15: =IFERROR(__xludf.DUMMYFUNCTION("IFERROR($E15/INDEX(prs!$D$30:$D$36,MATCH(TRUE,ARRAYFORMULA(ISNUMBER(SEARCH(prs!$A$30:$A$36,$B15))),0)),"""")"),"") | M15: =IFERROR(__xludf.DUMMYFUNCTION("IFERROR($L15/INDEX(prs!$D$30:$D$36,MATCH(TRUE,ARRAYFORMULA(ISNUMBER(SEARCH(prs!$A$30:$A$36,$I15))),0)),"""")"),"") | T15: =IFERROR(__xludf.DUMMYFUNCTION("IFERROR($S15/INDEX(prs!$D$30:$D$36,MATCH(TRUE,ARRAYFORMULA(ISNUMBER(SEARCH(prs!$A$30:$A$36,$P15))),0)),"""")"),"") | AA15: =IFERROR(__xludf.DUMMYFUNCTION("IFERROR($Z15/INDEX(prs!$D$30:$D$36,MATCH(TRUE,ARRAYFORMULA(ISNUMBER(SEARCH(prs!$A$30:$A$36,$W15))),0)),"""")"),"")
C16: SEMANA 01 | J16: SEMANA 02 | Q16: SEMANA 03 | X16: SEMANA 04
A18: TREINO 02
C19: SETS | D19: REPS | E19: KG | F19: %1RM | G19: OBS | J19: SETS | K19: REPS | L19: KG | M19: %1RM | N19: OBS | Q19: SETS | R19: REPS | S19: KG | T19: %1RM | U19: OBS | X19: SETS | Y19: REPS | Z19: KG | AA19: %1RM | AB19: OBS
B20: exercícios | F20: pse | I20: exercícios | M20: pse | P20: exercícios | T20: pse | W20: exercícios | AA20: pse
F21: =IFERROR(__xludf.DUMMYFUNCTION("IFERROR($E21/INDEX(prs!$D$30:$D$36,MATCH(TRUE,ARRAYFORMULA(ISNUMBER(SEARCH(prs!$A$30:$A$36,$B21))),0)),"""")"),"") | M21: =IFERROR(__xludf.DUMMYFUNCTION("IFERROR($L21/INDEX(prs!$D$30:$D$36,MATCH(TRUE,ARRAYFORMULA(ISNUMBER(SEARCH(prs!$A$30:$A$36,$I21))),0)),"""")"),"") | T21: =IFERROR(__xludf.DUMMYFUNCTION("IFERROR($S21/INDEX(prs!$D$30:$D$36,MATCH(TRUE,ARRAYFORMULA(ISNUMBER(SEARCH(prs!$A$30:$A$36,$P21))),0)),"""")"),"") | AA21: =IFERROR(__xludf.DUMMYFUNCTION("IFERROR($Z21/INDEX(prs!$D$30:$D$36,MATCH(TRUE,ARRAYFORMULA(ISNUMBER(SEARCH(prs!$A$30:$A$36,$W21))),0)),"""")"),"")
F22: =IFERROR(__xludf.DUMMYFUNCTION("IFERROR($E22/INDEX(prs!$D$30:$D$36,MATCH(TRUE,ARRAYFORMULA(ISNUMBER(SEARCH(prs!$A$30:$A$36,$B22))),0)),"""")"),"") | M22: =IFERROR(__xludf.DUMMYFUNCTION("IFERROR($L22/INDEX(prs!$D$30:$D$36,MATCH(TRUE,ARRAYFORMULA(ISNUMBER(SEARCH(prs!$A$30:$A$36,$I22))),0)),"""")"),"") | T22: =IFERROR(__xludf.DUMMYFUNCTION("IFERROR($S22/INDEX(prs!$D$30:$D$36,MATCH(TRUE,ARRAYFORMULA(ISNUMBER(SEARCH(prs!$A$30:$A$36,$P22))),0)),"""")"),"") | AA22: =IFERROR(__xludf.DUMMYFUNCTION("IFERROR($Z22/INDEX(prs!$D$30:$D$36,MATCH(TRUE,ARRAYFORMULA(ISNUMBER(SEARCH(prs!$A$30:$A$36,$W22))),0)),"""")"),"")
F23: =IFERROR(__xludf.DUMMYFUNCTION("IFERROR($E23/INDEX(prs!$D$30:$D$36,MATCH(TRUE,ARRAYFORMULA(ISNUMBER(SEARCH(prs!$A$30:$A$36,$B23))),0)),"""")"),"") | M23: =IFERROR(__xludf.DUMMYFUNCTION("IFERROR($L23/INDEX(prs!$D$30:$D$36,MATCH(TRUE,ARRAYFORMULA(ISNUMBER(SEARCH(prs!$A$30:$A$36,$I23))),0)),"""")"),"") | T23: =IFERROR(__xludf.DUMMYFUNCTION("IFERROR($S23/INDEX(prs!$D$30:$D$36,MATCH(TRUE,ARRAYFORMULA(ISNUMBER(SEARCH(prs!$A$30:$A$36,$P23))),0)),"""")"),"") | AA23: =IFERROR(__xludf.DUMMYFUNCTION("IFERROR($Z23/INDEX(prs!$D$30:$D$36,MATCH(TRUE,ARRAYFORMULA(ISNUMBER(SEARCH(prs!$A$30:$A$36,$W23))),0)),"""")"),"")
